Workbook

Sheet 01.01.26см1
A1: Дата | B1: 01.01.2026 | F1: Смена | G1: 1 | AE1: Мельница №5
B2: Плотность, % | N2: Ситовой анализ, % -74мкм | P2: Производительность мельниц, тн/ч | U2: все мельницы | V2: Выпуск МКР | W2: Время | X2: на начало смены | Y2: на конец смены | Z2: переработка по счетчику | AA2: № | AB2: Переработка Ручной замер | AE2: мин | AF2: тонн
A3: Время | B3: Слив мельниц | G3: Слив гидроциклона | I3: Сгуститель | K3: Классификатор | N3: Гидроциклон | AA3: МШР | AE3: 1 | AF3: =AE3*40/60 -> 0.66666667
B4: 1 | C4: 2 | D4: 3 | E4: 4 | F4: 5 | G4: 1ст | H4: 2ст | I4: 1 | J4: 2 | K4: 1 | L4: 3 | M4: 5 | N4: 1ст | O4: 2ст | P4: 1 | Q4: 2 | R4: 3 | S4: 4 | T4: 5 | AB4: Время | AC4: Мельница | AD4: Ручной | AE4: 2 | AF4: =AE4*40/60 -> 1.3333333
A5: 21 | P5: 34.5 | Q5: 0 | R5: 0 | S5: 31 | T5: 11.43 | U5: =SUM(P5:T5) -> 76.93 | W5: 21 | X5: ='[1]31.12.25см2'!Y5 -> 510168.7 | Y5: =X5+P17 -> 510645.7 | Z5: =Y5-X5 -> 477 | AA5: 1 | AE5: 3 | AF5: =AE5*40/60 -> 2
A6: 22 | P6: 38.4 | Q6: 0 | R6: 0 | S6: 33 | T6: 12.1 | U6: =SUM(P6:T6) -> 83.5 | W6: 22 | X6: ='[1]31.12.25см2'!Y6 -> 810050.11 | Y6: =X6+R17 -> 810050.11 | Z6: =Y6-X6 -> 0 | AA6: 3 | AE6: 4 | AF6: =AE6*40/60 -> 2.6666667
A7: 23 | B7: 70 | C7: 58 | E7: 68 | F7: 64 | G7: 44 | H7: 30 | K7: 60 | M7: 51 | N7: 53 | O7: 75 | P7: 39.6 | Q7: 0 | R7: 0 | S7: 33 | T7: 13.88 | U7: =SUM(P7:T7) -> 86.48 | V7: 1 | W7: 23 | X7: ='[1]31.12.25см2'!Y7 -> 502129 | Y7: =X7+S17 -> 502531 | Z7: =Y7-X7 -> 402 | AA7: 4 | AB7: 0.875 | AC7: №1 | AD7: 40 | AE7: 5 | AF7: =AE7*40/60 -> 3.3333333
A8: 24 | P8: 39.5 | Q8: 0 | R8: 0 | S8: 35 | T8: 12.9 | U8: =SUM(P8:T8) -> 87.4 | W8: 24 | X8: ='[1]31.12.25см2'!Y8 -> 8613.78 | Y8: =X8+T17 -> 8759.978 | Z8: =T17 -> 146.198 | AA8: 5 | AC8: №3 | AE8: 6 | AF8: =AE8*40/60 -> 4
A9: 1 | P9: 40 | Q9: 0 | R9: 0 | S9: 34 | T9: 12 | U9: =SUM(P9:T9) -> 86 | V9: 1 | W9: 1 | X9: Итого производ - ность за смену | Z9: =SUM(Z5:Z8) -> 1025.198 | AC9: №4 | AD9: 31 | AE9: 7 | AF9: =AE9*40/60 -> 4.6666667
A10: 2 | P10: 40.3 | Q10: 0 | R10: 0 | S10: 34 | T10: 11.635 | U10: =SUM(P10:T10) -> 85.935 | V10: 1 | W10: 2 | AC10: №5 | AD10: 12 | AE10: 8 | AF10: =AE10*40/60 -> 5.3333333
A11: 3 | P11: 39.5 | Q11: 0 | R11: 0 | S11: 33 | T11: 11.554 | U11: =SUM(P11:T11) -> 84.054 | V11: 1 | W11: 3 | X11: Руда с конвейера Сито 12 мм | AE11: 9 | AF11: =AE11*40/60 -> 6
A12: 4 | P12: 39.8 | Q12: 0 | R12: 0 | S12: 34 | T12: 11.44 | U12: =SUM(P12:T12) -> 85.24 | V12: 3 | W12: 4 | AB12: 0.95833333 | AC12: №1 | AD12: 40 | AE12: 10 | AF12: =AE12*40/60 -> 6.6666667
A13: 5 | B13: 68 | C13: 62 | E13: 68 | F13: 66 | G13: 45 | H13: 32 | K13: 54 | M13: 49 | N13: 50 | O13: 72 | P13: 40.1 | Q13: 0 | R13: 0 | S13: 34 | T13: 11.584 | U13: =SUM(P13:T13) -> 85.684 | W13: 5 | X13: Время | Y13: Мельница | Z13: + | AA13: - | AC13: №3 | AE13: 11 | AF13: =AE13*40/60 -> 7.3333333
A14: 6 | P14: 41.7 | Q14: 0 | R14: 0 | S14: 34 | T14: 13.431 | U14: =SUM(P14:T14) -> 89.131 | V14: 2 | W14: 6 | X14: 0.91666667 | Y14: Исходная руда №1 | Z14: 1.2 | AA14: =100-Z14 -> 98.8 | AC14: №4 | AD14: 33 | AE14: 12 | AF14: =AE14*40/60 -> 8
A15: 7 | P15: 40.4 | Q15: 0 | R15: 0 | S15: 33 | T15: 12.854 | U15: =SUM(P15:T15) -> 86.254 | W15: 7 | Y15: Исходная руда №3 | AA15: =100-Z15 -> 100 | AC15: №5 | AD15: 12 | AE15: 13 | AF15: =AE15*40/60 -> 8.6666667
A16: 8 | P16: 43.2 | Q16: 0 | R16: 0 | S16: 34 | T16: 11.39 | U16: =SUM(P16:T16) -> 88.59 | V16: 1 | W16: 8 | Y16: Исходная руда №4 | Z16: 1.6 | AA16: =100-Z16 -> 98.4 | AE16: 14 | AF16: =AE16*40/60 -> 9.3333333
A17: среднее | B17: =AVERAGE(B5:B15) -> 69 | C17: =AVERAGE(C5:C16) -> 60 | D17: =AVERAGE(D5:D15) -> #DIV/0! | E17: =AVERAGE(E5:E15) -> 68 | F17: =AVERAGE(F5:F15) -> 65 | G17: =AVERAGE(G5:G16) -> 44.5 | H17: =AVERAGE(H5:H16) -> 31 | I17: =AVERAGE(I5:I15) -> #DIV/0! | J17: =AVERAGE(J5:J15) -> #DIV/0! | K17: =AVERAGE(K5:K15) -> 57 | L17: =AVERAGE(L5:L15) -> #DIV/0! | M17: =AVERAGE(M5:M15) -> 50 | N17: =AVERAGE(N5:N15) -> 51.5 | O17: =AVERAGE(O5:O16) -> 73.5 | P17: =SUM(P5:P16) -> 477 | Q17: =SUM(Q5:Q16) -> 0 | R17: =SUM(R5:R16) -> 0 | S17: =SUM(S5:S16) -> 402 | T17: =SUM(T5:T16) -> 146.198 | U17: =SUM(P17:T17) -> 1025.198 | V17: =SUM(V5:V16) -> 10 | Y17: Исходная руда №5 | Z17: 0.9 | AA17: =100-Z17 -> 99.1 | AB17: 0.041666667 | AC17: №1 | AD17: 41 | AE17: 15 | AF17: =AE17*40/60 -> 10
AA18: =(AA14+AA16+AA17)/3 -> 98.766667 | AC18: №3 | AE18: 16 | AF18: =AE18*40/60 -> 10.666667
A19: Загрузка шаров мельниц | C19: Ø, мм | D19: тн | F19: Примечание | I19: Ситовый анализ 31.12.25 см 2 | M19: Влага руды, % | P19: 1.7 | S19: 1.8 | T19: 1.8 | U19: =(U17-U20)/U17*100 -> 1.7534724 | X19: 0.041666667 | AA19: - | AC19: №4 | AD19: 35 | AE19: 17 | AF19: =AE19*40/60 -> 11.333333
A20: №1 | C20: 60 | D20: 0.2 | F20: новые | K20: % | M20: Итого СМТ по весам за смену | P20: =(P17-(P17*P19/100)) -> 468.891 | R20: =(R17-(R17*R19/100)) -> 0 | S20: =(S17-(S17*S19/100)) -> 394.764 | T20: =(T17-(T17*T19/100)) -> 143.56644 | U20: =P20+Q20+R20+S20+T20 -> 1007.2214 | Y20: Исходная руда №1 | Z20: 0.9 | AA20: =100-Z20 -> 99.1 | AC20: №5 | AD20: 12 | AE20: 18 | AF20: =AE20*40/60 -> 12
A21: №2 | C21: 30 | D21: 0.15 | F21: новые | I21: ГЦ№1 | J21: 48 | M21: Итого СМТ замер за смену | P21: =(U17-(U17*U19/100)) -> 1007.2214 | Y21: Исходная руда №3 | AA21: =100-Z21 -> 100 | AE21: 19 | AF21: =AE21*40/60 -> 12.666667
A22: №4 | C22: 60 | D22: 0.2 | F22: новые | I22: 100 | J22: =I22-J21 -> 52 | K22: =J22/I22*100 -> 52 | Y22: Исходная руда №4 | Z22: 1.2 | AA22: =100-Z22 -> 98.8 | AB22: 0.125 | AC22: №1 | AD22: 40 | AE22: 20 | AF22: =AE22*40/60 -> 13.333333
A23: №5 | C23: 60 | D23: 0.1 | F23: новые | I23: ГЦ№2 | J23: 26 | M23: Итого за сутки: | Y23: Исходная руда №5 | Z23: 1.3 | AA23: =100-Z23 -> 98.7 | AC23: №3 | AE23: 21 | AF23: =AE23*40/60 -> 14
I24: 100 | J24: =I24-J23 -> 74 | K24: =J24/I24*100 -> 74 | M24: Итого с начала месяца: | AA24: =(AA20+AA22+AA23)/3 -> 98.866667 | AC24: №4 | AD24: 33 | AE24: 22 | AF24: =AE24*40/60 -> 14.666667
X25: 0.125 | AA25: - | AC25: №5 | AD25: 10 | AE25: 23 | AF25: =AE25*40/60 -> 15.333333
Y26: Исходная руда №1 | Z26: 1.1 | AA26: =100-Z26 -> 98.9 | AE26: 24 | AF26: =AE26*40/60 -> 16
A27: Простой мельниц | C27: с | D27: до | F27: кол-во мин | H27: Причины простоя | Y27: Исходная руда №3 | AA27: =100-Z27 -> 100 | AB27: 0.20833333 | AC27: №1 | AD27: 41 | AE27: 25 | AF27: =AE27*40/60 -> 16.666667
A28: №3 | C28: 0.83333333 | D28: 0.33333333 | F28: 12часов | H28: МШР стоит - ППР. | Y28: Исходная руда №4 | Z28: 1.7 | AA28: =100-Z28 -> 98.3 | AC28: №3 | AE28: 26 | AF28: =AE28*40/60 -> 17.333333
H29: МШР №4 ручной замер - сбой эл счетчика. | Y29: Исходная руда №5 | Z29: 1 | AA29: =100-Z29 -> 99 | AC29: №4 | AD29: 34 | AE29: 27 | AF29: =AE29*40/60 -> 18
H30: В 20:20-20:29 шуровка бункера МШР №1. 8 мин | AA30: =(AA26+AA28+AA29)/3 -> 98.733333 | AC30: №5 | AD30: 11 | AE30: 28 | AF30: =AE30*40/60 -> 18.666667
H31: В 1:00 обнулился счетчик на МШР №5 | X31: 0.20833333 | AA31: - | AE31: 29 | AF31: =AE31*40/60 -> 19.333333
Y32: Исходная руда №1 | Z32: 1 | AA32: =100-Z32 -> 99 | AB32: 0.29166667 | AC32: №1 | AD32: 42 | AE32: 30 | AF32: =AE32*40/60 -> 20
Y33: Исходная руда №3 | AA33: =100-Z33 -> 100 | AC33: №3 | AE33: 31 | AF33: =AE33*40/60 -> 20.666667
Y34: Исходная руда №4 | Z34: 1.2 | AA34: =100-Z34 -> 98.8 | AC34: №4 | AD34: 33 | AE34: 32 | AF34: =AE34*40/60 -> 21.333333
Y35: Исходная руда №5 | Z35: 0.9 | AA35: =100-Z35 -> 99.1 | AC35: №5 | AD35: 10 | AE35: 33 | AF35: =AE35*40/60 -> 22
AA36: =(AA32+AA34+AA35)/3 -> 98.966667 | AE36: 34 | AF36: =AE36*40/60 -> 22.666667
AE37: 35 | AF37: =AE37*40/60 -> 23.333333
AE38: 36 | AF38: =AE38*40/60 -> 24
AE39: 37 | AF39: =AE39*40/60 -> 24.666667
A40: Остаток МКР на начало смены | D40: 73 | AE40: 38 | AF40: =AE40*40/60 -> 25.333333
...

Sheet 01.01.26см2
A1: Дата | B1: 01.01.2026 | F1: Смена | G1: 2 | AE1: Мельница №5
B2: Плотность, % | N2: Ситовой анализ, % -74мкм | P2: Производительность мельниц, тн/ч | U2: все мельницы | V2: Выпуск МКР | W2: Время | X2: на начало смены | Y2: на конец смены | Z2: переработка по счетчику | AA2: № | AB2: Переработка Ручной замер | AE2: мин | AF2: тонн
A3: Время | B3: Слив мельниц | G3: Слив гидроциклона | I3: Сгуститель | K3: Классификатор | N3: Гидроциклон | AA3: МШР | AE3: 1 | AF3: =AE3*11/60 -> 0.18333333
B4: 1 | C4: 2 | D4: 3 | E4: 4 | F4: 5 | G4: 1ст | H4: 2ст | I4: 1 | J4: 2 | K4: 1 | L4: 3 | M4: 5 | N4: 1ст | O4: 2ст | P4: 1 | Q4: 2 | R4: 3 | S4: 4 | T4: 5 | AB4: Время | AC4: Мельница | AD4: Ручной | AE4: 2 | AF4: =AE4*11/60 -> 0.36666667
A5: 9 | P5: 43.3 | Q5: 0 | R5: 0 | S5: 34 | T5: 10.844 | U5: =SUM(P5:T5) -> 88.144 | V5: 1 | W5: 9 | X5: 510645.7 | Y5: 511132.9 | Z5: =Y5-X5 -> 487.2 | AA5: 1 | AE5: 3 | AF5: =AE5*11/60 -> 0.55
A6: 10 | P6: 43.3 | Q6: 0 | R6: 0 | S6: 27 | T6: 11.356 | U6: =SUM(P6:T6) -> 81.656 | W6: 10 | X6: 810050.11 | Y6: =X6+R17 -> 810050.11 | Z6: =Y6-X6 -> 0 | AA6: 3 | AE6: 4 | AF6: =AE6*11/60 -> 0.73333333
A7: 11 | B7: 69 | C7: 53 | E7: 63 | F7: 68 | G7: 46 | H7: 36 | K7: 56 | M7: 47 | N7: 53 | O7: 71 | P7: 41.7 | Q7: 0 | R7: 0 | S7: 32 | T7: 12.079 | U7: =SUM(P7:T7) -> 85.779 | W7: 11 | X7: ='01.01.26см1'!Y7 -> 502531 | Y7: =X7+S17 -> 502926 | Z7: =Y7-X7 -> 395 | AA7: 4 | AB7: 0.375 | AC7: №1 | AD7: 41 | AE7: 5 | AF7: =AE7*11/60 -> 0.91666667
A8: 12 | I8: 0 | J8: 9 | P8: 39.9 | Q8: 0 | R8: 0 | S8: 31 | T8: 11.918 | U8: =SUM(P8:T8) -> 82.818 | V8: 2 | W8: 12 | X8: 101.317 | Y8: =X8+T17 -> 237.889 | Z8: =T17 -> 136.572 | AA8: 5 | AC8: №3 | AE8: 6 | AF8: =AE8*11/60 -> 1.1
A9: 13 | P9: 41.9 | Q9: 0 | R9: 0 | S9: 34 | T9: 12.655 | U9: =SUM(P9:T9) -> 88.555 | W9: 13 | X9: Итого производ - ность за смену | Z9: =SUM(Z5:Z8) -> 1018.772 | AC9: №4 | AD9: 35 | AE9: 7 | AF9: =AE9*11/60 -> 1.2833333
A10: 14 | P10: 41.2 | Q10: 0 | R10: 0 | S10: 34 | T10: 11.772 | U10: =SUM(P10:T10) -> 86.972 | W10: 14 | AC10: №5 | AD10: 10 | AE10: 8 | AF10: =AE10*11/60 -> 1.4666667
A11: 15 | P11: 37.8 | Q11: 0 | R11: 0 | S11: 35 | T11: 12.113 | U11: =SUM(P11:T11) -> 84.913 | V11: 1 | W11: 15 | X11: Руда с конвейера Сито 12 мм | AE11: 9 | AF11: =AE11*11/60 -> 1.65
A12: 16 | P12: 38.6 | Q12: 0 | R12: 0 | S12: 33 | T12: 11.62 | U12: =SUM(P12:T12) -> 83.22 | V12: 2 | W12: 16 | AB12: 0.45833333 | AC12: №1 | AD12: 40 | AE12: 10 | AF12: =AE12*11/60 -> 1.8333333
A13: 17 | B13: 69 | C13: 51 | E13: 63 | F13: 65 | G13: 43 | H13: 29 | I13: 17 | J13: 4 | K13: 53 | M13: 48 | N13: 54 | O13: 73 | P13: 40.3 | Q13: 0 | R13: 0 | S13: 33 | T13: 10.62 | U13: =SUM(P13:T13) -> 83.92 | W13: 17 | X13: Время | Y13: Мельница | Z13: + | AA13: - | AC13: №3 | AE13: 11 | AF13: =AE13*11/60 -> 2.0166667
A14: 18 | P14: 35 | Q14: 0 | R14: 0 | S14: 33 | T14: 10.971 | U14: =SUM(P14:T14) -> 78.971 | V14: 1 | W14: 18 | X14: 0.41666667 | Y14: Исходная руда №1 | Z14: 0.3 | AA14: =100-Z14 -> 99.7 | AC14: №4 | AD14: 32 | AE14: 12 | AF14: =AE14*11/60 -> 2.2
A15: 19 | P15: 43.7 | Q15: 0 | R15: 0 | S15: 35 | T15: 11.013 | U15: =SUM(P15:T15) -> 89.713 | W15: 19 | Y15: Исходная руда №3 | AA15: =100-Z15 -> 100 | AC15: №5 | AD15: 10 | AE15: 13 | AF15: =AE15*11/60 -> 2.3833333
A16: 20 | P16: 40.5 | Q16: 0 | R16: 0 | S16: 34 | T16: 9.611 | U16: =SUM(P16:T16) -> 84.111 | V16: 1 | W16: 20 | Y16: Исходная руда №4 | Z16: 0.4 | AA16: =100-Z16 -> 99.6 | AE16: 14 | AF16: =AE16*11/60 -> 2.5666667
A17: среднее | B17: =AVERAGE(B5:B15) -> 69 | C17: =AVERAGE(C5:C16) -> 52 | D17: =AVERAGE(D5:D15) -> #DIV/0! | E17: =AVERAGE(E5:E15) -> 63 | F17: =AVERAGE(F5:F15) -> 66.5 | G17: =AVERAGE(G5:G16) -> 44.5 | H17: =AVERAGE(H5:H16) -> 32.5 | I17: =AVERAGE(I5:I15) -> 8.5 | J17: =AVERAGE(J5:J15) -> 6.5 | K17: =AVERAGE(K5:K15) -> 54.5 | L17: =AVERAGE(L5:L15) -> #DIV/0! | M17: =AVERAGE(M5:M15) -> 47.5 | N17: =AVERAGE(N5:N15) -> 53.5 | O17: =AVERAGE(O5:O16) -> 72 | P17: =SUM(P5:P16) -> 487.2 | Q17: =SUM(Q5:Q16) -> 0 | R17: =SUM(R5:R16) -> 0 | S17: =SUM(S5:S16) -> 395 | T17: =SUM(T5:T16) -> 136.572 | U17: =SUM(P17:T17) -> 1018.772 | V17: =SUM(V5:V16) -> 8 | Y17: Исходная руда №5 | Z17: 0.3 | AA17: =100-Z17 -> 99.7 | AB17: 0.54166667 | AC17: №1 | AD17: 41 | AE17: 15 | AF17: =AE17*11/60 -> 2.75
AA18: 99.67 | AC18: №3 | AE18: 16 | AF18: =AE18*11/60 -> 2.9333333
A19: Загрузка шаров мельниц | C19: Ø, мм | D19: тн | F19: Примечание | I19: Ситовый анализ 01.01.26 см 1 | M19: Влага руды, % | P19: 2 | S19: 1.8 | T19: 2.2 | U19: =(U17-U20)/U17*100 -> 1.9492668 | X19: 0.5 | AA19: - | AC19: №4 | AD19: 34 | AE19: 17 | AF19: =AE19*11/60 -> 3.1166667
A20: №1 | C20: 60 | D20: 0.2 | F20: новые | K20: % | M20: Итого СМТ по весам за смену | P20: =(P17-(P17*P19/100)) -> 477.456 | R20: =(R17-(R17*R19/100)) -> 0 | S20: =(S17-(S17*S19/100)) -> 387.89 | T20: =(T17-(T17*T19/100)) -> 133.56742 | U20: =P20+Q20+R20+S20+T20 -> 998.91342 | Y20: Исходная руда №1 | Z20: 0.2 | AA20: =100-Z20 -> 99.8 | AC20: №5 | AD20: 10 | AE20: 18 | AF20: =AE20*11/60 -> 3.3
A21: №2 | C21: 30 | D21: 0.2 | F21: новые | I21: ГЦ№1 | J21: 47 | M21: Итого СМТ замер за смену | P21: =(U17-(U17*U19/100)) -> 998.91342 | Y21: Исходная руда №3 | AA21: =100-Z21 -> 100 | AE21: 19 | AF21: =AE21*11/60 -> 3.4833333
A22: №4 | C22: 60 | D22: 0.2 | F22: новые | I22: 100 | J22: =I22-J21 -> 53 | K22: =J22/I22*100 -> 53 | Y22: Исходная руда №4 | Z22: 0.2 | AA22: =100-Z22 -> 99.8 | AB22: 0.625 | AC22: №1 | AD22: 41 | AE22: 20 | AF22: =AE22*11/60 -> 3.6666667
A23: №5 | C23: 60 | D23: 0.1 | F23: новые | I23: ГЦ№2 | J23: 28 | M23: Итого за сутки: | Y23: Исходная руда №5 | Z23: 0.3 | AA23: =100-Z23 -> 99.7 | AC23: №3 | AE23: 21 | AF23: =AE23*11/60 -> 3.85
I24: 100 | J24: =I24-J23 -> 72 | K24: =J24/I24*100 -> 72 | M24: Итого с начала месяца: | AA24: 99.76 | AC24: №4 | AD24: 35 | AE24: 22 | AF24: =AE24*11/60 -> 4.0333333
X25: 0.625 | AA25: - | AC25: №5 | AD25: 10 | AE25: 23 | AF25: =AE25*11/60 -> 4.2166667
Y26: Исходная руда №1 | Z26: 0.4 | AA26: =100-Z26 -> 99.6 | AE26: 24 | AF26: =AE26*11/60 -> 4.4
A27: Простой мельниц | C27: с | D27: до | F27: кол-во мин | H27: Причины простоя | Y27: Исходная руда №3 | AA27: =100-Z27 -> 100 | AB27: 0.70833333 | AC27: №1 | AD27: 41 | AE27: 25 | AF27: =AE27*11/60 -> 4.5833333
A28: №3 | C28: 0.33333333 | D28: 0.83333333 | F28: 12 часов | H28: МШР стоит - ППР. | Y28: Исходная руда №4 | Z28: 0.6 | AA28: =100-Z28 -> 99.4 | AC28: №3 | AE28: 26 | AF28: =AE28*11/60 -> 4.7666667
H29: С 10:00 МШР №4 ручной замер - сбой эл счетчика. | Y29: Исходная руда №5 | Z29: 0.3 | AA29: =100-Z29 -> 99.7 | AC29: №4 | AD29: 33 | AE29: 27 | AF29: =AE29*11/60 -> 4.95
H30: В 14:32 - 14:37 шуровка бункера МШР №1 5мин. | AA30: 99.57 | AC30: №5 | AD30: 10 | AE30: 28 | AF30: =AE30*11/60 -> 5.1333333
H31: В 17:30-17:39 остановили питание МШР №1 - перегруз. 9 мин | X31: 0.70833333 | AA31: - | AE31: 29 | AF31: =AE31*11/60 -> 5.3166667
Y32: Исходная руда №1 | Z32: 0.3 | AA32: =100-Z32 -> 99.7 | AB32: 0.79166667 | AC32: №1 | AD32: 41 | AE32: 30 | AF32: =AE32*11/60 -> 5.5
Y33: Исходная руда №3 | AA33: =100-Z33 -> 100 | AC33: №3 | AE33: 31 | AF33: =AE33*11/60 -> 5.6833333
Y34: Исходная руда №4 | Z34: 0.8 | AA34: =100-Z34 -> 99.2 | AC34: №4 | AD34: 35 | AE34: 32 | AF34: =AE34*11/60 -> 5.8666667
Y35: Исходная руда №5 | Z35: 0.4 | AA35: =100-Z35 -> 99.6 | AC35: №5 | AD35: 10 | AE35: 33 | AF35: =AE35*11/60 -> 6.05
AA36: 99.5 | AE36: 34 | AF36: =AE36*11/60 -> 6.2333333
AE37: 35 | AF37: =AE37*11/60 -> 6.4166667
AE38: 36 | AF38: =AE38*11/60 -> 6.6
AE39: 37 | AF39: =AE39*11/60 -> 6.7833333
A40: Остаток МКР на начало смены | D40: 83 | AE40: 38 | AF40: =AE40*11/60 -> 6.9666667
...

Sheet 02.01.26см1
A1: Дата | B1: 02.01.2026 | F1: Смена | G1: 1 | AE1: Мельница №5
B2: Плотность, % | N2: Ситовой анализ, % -74мкм | P2: Производительность мельниц, тн/ч | U2: все мельницы | V2: Выпуск МКР | W2: Время | X2: на начало смены | Y2: на конец смены | Z2: переработка по счетчику | AA2: № | AB2: Переработка Ручной замер | AE2: мин | AF2: тонн
A3: Время | B3: Слив мельниц | G3: Слив гидроциклона | I3: Сгуститель | K3: Классификатор | N3: Гидроциклон | AA3: МШР | AE3: 1 | AF3: =AE3*40/60 -> 0.66666667
B4: 1 | C4: 2 | D4: 3 | E4: 4 | F4: 5 | G4: 1ст | H4: 2ст | I4: 1 | J4: 2 | K4: 1 | L4: 3 | M4: 5 | N4: 1ст | O4: 2ст | P4: 1 | Q4: 2 | R4: 3 | S4: 4 | T4: 5 | AB4: Время | AC4: Мельница | AD4: Ручной | AE4: 2 | AF4: =AE4*40/60 -> 1.3333333
A5: 21 | P5: 34 | Q5: 0 | R5: 0 | S5: 34 | T5: 10.468 | U5: =SUM(P5:T5) -> 78.468 | W5: 21 | X5: ='01.01.26см2'!Y5 -> 511132.9 | Y5: =X5+P17 -> 511610.7 | Z5: =Y5-X5 -> 477.8 | AA5: 1 | AE5: 3 | AF5: =AE5*40/60 -> 2
A6: 22 | P6: 40 | Q6: 0 | R6: 0 | S6: 33 | T6: 10.765 | U6: =SUM(P6:T6) -> 83.765 | W6: 22 | X6: ='[1]31.12.25см2'!Y6 -> 810050.11 | Y6: =X6+R17 -> 810050.11 | Z6: =Y6-X6 -> 0 | AA6: 3 | AE6: 4 | AF6: =AE6*40/60 -> 2.6666667
A7: 23 | P7: 39 | Q7: 0 | R7: 0 | S7: 33 | T7: 10.928 | U7: =SUM(P7:T7) -> 82.928 | W7: 23 | X7: ='01.01.26см2'!Y7 -> 502926 | Y7: =X7+S17 -> 503328 | Z7: =Y7-X7 -> 402 | AA7: 4 | AB7: 0.875 | AC7: №1 | AD7: 40 | AE7: 5 | AF7: =AE7*40/60 -> 3.3333333
A8: 24 | B8: 66 | C8: 58 | E8: 69 | F8: 62 | G8: 45 | H8: 31 | K8: 55 | M8: 51 | N8: 52 | O8: 72 | P8: 41.1 | Q8: 0 | R8: 0 | S8: 34 | T8: 11.545 | U8: =SUM(P8:T8) -> 86.645 | V8: 1 | W8: 24 | X8: ='01.01.26см2'!Y8 -> 237.889 | Y8: =X8+T17 -> 375.175 | Z8: =T17 -> 137.286 | AA8: 5 | AC8: №3 | AE8: 6 | AF8: =AE8*40/60 -> 4
A9: 1 | P9: 41.6 | Q9: 0 | R9: 0 | S9: 34 | T9: 10.427 | U9: =SUM(P9:T9) -> 86.027 | V9: 1 | W9: 1 | X9: Итого производ - ность за смену | Z9: =SUM(Z5:Z8) -> 1017.086 | AC9: №4 | AD9: 34 | AE9: 7 | AF9: =AE9*40/60 -> 4.6666667
A10: 2 | P10: 41 | Q10: 0 | R10: 0 | S10: 33 | T10: 11.382 | U10: =SUM(P10:T10) -> 85.382 | W10: 2 | AC10: №5 | AD10: 10 | AE10: 8 | AF10: =AE10*40/60 -> 5.3333333
A11: 3 | P11: 40.8 | Q11: 0 | R11: 0 | S11: 33 | T11: 11.854 | U11: =SUM(P11:T11) -> 85.654 | V11: 2 | W11: 3 | X11: Руда с конвейера Сито 12 мм | AE11: 9 | AF11: =AE11*40/60 -> 6
A12: 4 | P12: 40.9 | Q12: 0 | R12: 0 | S12: 32 | T12: 12.003 | U12: =SUM(P12:T12) -> 84.903 | W12: 4 | AB12: 0.95833333 | AC12: №1 | AD12: 40 | AE12: 10 | AF12: =AE12*40/60 -> 6.6666667
A13: 5 | B13: 69 | C13: 61 | E13: 68 | F13: 68 | G13: 45 | H13: 33 | K13: 58 | M13: 46 | N13: 50 | O13: 73 | P13: 40 | Q13: 0 | R13: 0 | S13: 34 | T13: 11.773 | U13: =SUM(P13:T13) -> 85.773 | V13: 1 | W13: 5 | X13: Время | Y13: Мельница | Z13: + | AA13: - | AC13: №3 | AE13: 11 | AF13: =AE13*40/60 -> 7.3333333
A14: 6 | P14: 40.3 | Q14: 0 | R14: 0 | S14: 34 | T14: 12.99 | U14: =SUM(P14:T14) -> 87.29 | W14: 6 | X14: 0.91666667 | Y14: Исходная руда №1 | Z14: 0.5 | AA14: =100-Z14 -> 99.5 | AC14: №4 | AD14: 33 | AE14: 12 | AF14: =AE14*40/60 -> 8
A15: 7 | P15: 39.3 | Q15: 0 | R15: 0 | S15: 33 | T15: 11.992 | U15: =SUM(P15:T15) -> 84.292 | V15: 2 | W15: 7 | Y15: Исходная руда №3 | AA15: =100-Z15 -> 100 | AC15: №5 | AD15: 10 | AE15: 13 | AF15: =AE15*40/60 -> 8.6666667
A16: 8 | P16: 39.8 | Q16: 0 | R16: 0 | S16: 35 | T16: 11.159 | U16: =SUM(P16:T16) -> 85.959 | V16: 1 | W16: 8 | Y16: Исходная руда №4 | Z16: 0.9 | AA16: =100-Z16 -> 99.1 | AE16: 14 | AF16: =AE16*40/60 -> 9.3333333
A17: среднее | B17: =AVERAGE(B5:B15) -> 67.5 | C17: =AVERAGE(C5:C16) -> 59.5 | D17: =AVERAGE(D5:D15) -> #DIV/0! | E17: =AVERAGE(E5:E15) -> 68.5 | F17: =AVERAGE(F5:F15) -> 65 | G17: =AVERAGE(G5:G16) -> 45 | H17: =AVERAGE(H5:H16) -> 32 | I17: =AVERAGE(I5:I15) -> #DIV/0! | J17: =AVERAGE(J5:J15) -> #DIV/0! | K17: =AVERAGE(K5:K15) -> 56.5 | L17: =AVERAGE(L5:L15) -> #DIV/0! | M17: =AVERAGE(M5:M15) -> 48.5 | N17: =AVERAGE(N5:N15) -> 51 | O17: =AVERAGE(O5:O16) -> 72.5 | P17: =SUM(P5:P16) -> 477.8 | Q17: =SUM(Q5:Q16) -> 0 | R17: =SUM(R5:R16) -> 0 | S17: =SUM(S5:S16) -> 402 | T17: =SUM(T5:T16) -> 137.286 | U17: =SUM(P17:T17) -> 1017.086 | V17: =SUM(V5:V16) -> 8 | Y17: Исходная руда №5 | Z17: 0.7 | AA17: =100-Z17 -> 99.3 | AB17: 0.041666667 | AC17: №1 | AD17: 41 | AE17: 15 | AF17: =AE17*40/60 -> 10
AA18: =(AA14+AA16+AA17)/3 -> 99.3 | AC18: №3 | AE18: 16 | AF18: =AE18*40/60 -> 10.666667
A19: Загрузка шаров мельниц | C19: Ø, мм | D19: тн | F19: Примечание | I19: Ситовый анализ 01.01.26 см 2 | M19: Влага руды, % | P19: 1.9 | S19: 2 | T19: 2.1 | U19: =(U17-U20)/U17*100 -> 1.9665206 | X19: 0.041666667 | AA19: - | AC19: №4 | AD19: 34 | AE19: 17 | AF19: =AE19*40/60 -> 11.333333
A20: №1 | C20: 60 | D20: 0.3 | F20: новые | K20: % | M20: Итого СМТ по весам за смену | P20: =(P17-(P17*P19/100)) -> 468.7218 | R20: =(R17-(R17*R19/100)) -> 0 | S20: =(S17-(S17*S19/100)) -> 393.96 | T20: =(T17-(T17*T19/100)) -> 134.40299 | U20: =P20+Q20+R20+S20+T20 -> 997.08479 | Y20: Исходная руда №1 | Z20: 0.9 | AA20: =100-Z20 -> 99.1 | AC20: №5 | AD20: 10 | AE20: 18 | AF20: =AE20*40/60 -> 12
A21: №2 | C21: 30 | D21: 0.2 | F21: новые | I21: ГЦ№1 | J21: 45 | M21: Итого СМТ замер за смену | P21: =(U17-(U17*U19/100)) -> 997.08479 | Y21: Исходная руда №3 | AA21: =100-Z21 -> 100 | AE21: 19 | AF21: =AE21*40/60 -> 12.666667
A22: №4 | C22: 60 | D22: 0.15 | F22: новые | I22: 100 | J22: =I22-J21 -> 55 | K22: =J22/I22*100 -> 55 | Y22: Исходная руда №4 | Z22: 0.5 | AA22: =100-Z22 -> 99.5 | AB22: 0.125 | AC22: №1 | AD22: 40 | AE22: 20 | AF22: =AE22*40/60 -> 13.333333
A23: №5 | C23: 60 | D23: 0.15 | F23: новые | I23: ГЦ№2 | J23: 27 | M23: Итого за сутки: | Y23: Исходная руда №5 | Z23: 0.7 | AA23: =100-Z23 -> 99.3 | AC23: №3 | AE23: 21 | AF23: =AE23*40/60 -> 14
I24: 100 | J24: =I24-J23 -> 73 | K24: =J24/I24*100 -> 73 | M24: Итого с начала месяца: | AA24: =(AA20+AA22+AA23)/3 -> 99.3 | AC24: №4 | AD24: 33 | AE24: 22 | AF24: =AE24*40/60 -> 14.666667
X25: 0.125 | AA25: - | AC25: №5 | AD25: 10 | AE25: 23 | AF25: =AE25*40/60 -> 15.333333
Y26: Исходная руда №1 | Z26: 1 | AA26: =100-Z26 -> 99 | AE26: 24 | AF26: =AE26*40/60 -> 16
A27: Простой мельниц | C27: с | D27: до | F27: кол-во мин | H27: Причины простоя | Y27: Исходная руда №3 | AA27: =100-Z27 -> 100 | AB27: 0.20833333 | AC27: №1 | AD27: 41 | AE27: 25 | AF27: =AE27*40/60 -> 16.666667
A28: №3 | C28: 0.83333333 | D28: 0.33333333 | F28: 12часов | H28: МШР стоит - ППР. | Y28: Исходная руда №4 | Z28: 1.7 | AA28: =100-Z28 -> 98.3 | AC28: №3 | AE28: 26 | AF28: =AE28*40/60 -> 17.333333
H29: МШР №4 ручной замер - сбой эл счетчика. | Y29: Исходная руда №5 | Z29: 1.4 | AA29: =100-Z29 -> 98.6 | AC29: №4 | AD29: 34 | AE29: 27 | AF29: =AE29*40/60 -> 18
H30: В 20:30-20:35 остановили питание МШР №1 - перегруз. 5 мин | AA30: =(AA26+AA28+AA29)/3 -> 98.633333 | AC30: №5 | AD30: 11 | AE30: 28 | AF30: =AE30*40/60 -> 18.666667
X31: 0.20833333 | AA31: - | AE31: 29 | AF31: =AE31*40/60 -> 19.333333
Y32: Исходная руда №1 | Z32: 0.8 | AA32: =100-Z32 -> 99.2 | AB32: 0.29166667 | AC32: №1 | AD32: 41 | AE32: 30 | AF32: =AE32*40/60 -> 20
Y33: Исходная руда №3 | AA33: =100-Z33 -> 100 | AC33: №3 | AE33: 31 | AF33: =AE33*40/60 -> 20.666667
Y34: Исходная руда №4 | Z34: 1.1 | AA34: =100-Z34 -> 98.9 | AC34: №4 | AD34: 33 | AE34: 32 | AF34: =AE34*40/60 -> 21.333333
Y35: Исходная руда №5 | Z35: 1 | AA35: =100-Z35 -> 99 | AC35: №5 | AD35: 10 | AE35: 33 | AF35: =AE35*40/60 -> 22
AA36: =(AA32+AA34+AA35)/3 -> 99.033333 | AE36: 34 | AF36: =AE36*40/60 -> 22.666667
AE37: 35 | AF37: =AE37*40/60 -> 23.333333
AE38: 36 | AF38: =AE38*40/60 -> 24
AE39: 37 | AF39: =AE39*40/60 -> 24.666667
A40: Остаток МКР на начало смены | D40: 91 | AE40: 38 | AF40: =AE40*40/60 -> 25.333333
...

Sheet 02.01.26см2
A1: Дата | B1: 02.01.2026 | F1: Смена | G1: 2 | AE1: Мельница №5
B2: Плотность, % | N2: Ситовой анализ, % -74мкм | P2: Производительность мельниц, тн/ч | U2: все мельницы | V2: Выпуск МКР | W2: Время | X2: на начало смены | Y2: на конец смены | Z2: переработка по счетчику | AA2: № | AB2: Переработка Ручной замер | AE2: мин | AF2: тонн
A3: Время | B3: Слив мельниц | G3: Слив гидроциклона | I3: Сгуститель | K3: Классификатор | N3: Гидроциклон | AA3: МШР | AE3: 1 | AF3: =AE3*11/60 -> 0.18333333
B4: 1 | C4: 2 | D4: 3 | E4: 4 | F4: 5 | G4: 1ст | H4: 2ст | I4: 1 | J4: 2 | K4: 1 | L4: 3 | M4: 5 | N4: 1ст | O4: 2ст | P4: 1 | Q4: 2 | R4: 3 | S4: 4 | T4: 5 | AB4: Время | AC4: Мельница | AD4: Ручной | AE4: 2 | AF4: =AE4*11/60 -> 0.36666667
A5: 9 | P5: 41.7 | Q5: 0 | R5: 0 | S5: 35 | T5: 10.501 | U5: =SUM(P5:T5) -> 87.201 | W5: 9 | X5: 511610.7 | Y5: =X5+P17 -> 512074.7 | Z5: =Y5-X5 -> 464 | AA5: 1 | AE5: 3 | AF5: =AE5*11/60 -> 0.55
A6: 10 | P6: 31.9 | Q6: 0 | R6: 0 | S6: 35 | T6: 11.456 | U6: =SUM(P6:T6) -> 78.356 | V6: 2 | W6: 10 | X6: 810050.11 | Y6: =X6+R17 -> 810050.11 | Z6: =Y6-X6 -> 0 | AA6: 3 | AE6: 4 | AF6: =AE6*11/60 -> 0.73333333
A7: 11 | B7: 67 | C7: 58 | E7: 62 | F7: 65 | G7: 46 | H7: 32 | I7: 48 | J7: 8 | K7: 55 | M7: 47 | N7: 49 | O7: 71 | P7: 42.9 | Q7: 0 | R7: 0 | S7: 34 | T7: 11.43 | U7: =SUM(P7:T7) -> 88.33 | V7: 1 | W7: 11 | X7: 503328 | Y7: =X7+S17 -> 503746 | Z7: =Y7-X7 -> 418 | AA7: 4 | AB7: 0.375 | AC7: №1 | AD7: 42 | AE7: 5 | AF7: =AE7*11/60 -> 0.91666667
A8: 12 | P8: 35 | Q8: 0 | R8: 0 | S8: 35 | T8: 10.862 | U8: =SUM(P8:T8) -> 80.862 | V8: 1 | W8: 12 | X8: 375.175 | Y8: =X8+T17 -> 510.691 | Z8: =T17 -> 135.516 | AA8: 5 | AC8: №3 | AE8: 6 | AF8: =AE8*11/60 -> 1.1
A9: 13 | P9: 38.9 | Q9: 0 | R9: 0 | S9: 34 | T9: 9.499 | U9: =SUM(P9:T9) -> 82.399 | W9: 13 | X9: Итого производ - ность за смену | Z9: =SUM(Z5:Z8) -> 1017.516 | AC9: №4 | AD9: 35 | AE9: 7 | AF9: =AE9*11/60 -> 1.2833333
A10: 14 | P10: 44.4 | Q10: 0 | R10: 0 | S10: 34 | T10: 11.493 | U10: =SUM(P10:T10) -> 89.893 | V10: 1 | W10: 14 | AC10: №5 | AD10: 10 | AE10: 8 | AF10: =AE10*11/60 -> 1.4666667
A11: 15 | P11: 42.5 | Q11: 0 | R11: 0 | S11: 35 | T11: 12.048 | U11: =SUM(P11:T11) -> 89.548 | V11: 1 | W11: 15 | X11: Руда с конвейера Сито 12 мм | AE11: 9 | AF11: =AE11*11/60 -> 1.65
A12: 16 | P12: 34.9 | Q12: 0 | R12: 0 | S12: 34 | T12: 11.429 | U12: =SUM(P12:T12) -> 80.329 | V12: 1 | W12: 16 | AB12: 0.45833333 | AC12: №1 | AD12: 41 | AE12: 10 | AF12: =AE12*11/60 -> 1.8333333
A13: 17 | B13: 69 | C13: 57 | E13: 64 | F13: 65 | G13: 43 | H13: 29 | I13: 2 | J13: 7 | K13: 53 | M13: 49 | N13: 54 | O13: 72 | P13: 30 | Q13: 0 | R13: 0 | S13: 35 | T13: 11.399 | U13: =SUM(P13:T13) -> 76.399 | V13: 1 | W13: 17 | X13: Время | Y13: Мельница | Z13: + | AA13: - | AC13: №3 | AE13: 11 | AF13: =AE13*11/60 -> 2.0166667
A14: 18 | P14: 40.4 | Q14: 0 | R14: 0 | S14: 36 | T14: 9.273 | U14: =SUM(P14:T14) -> 85.673 | V14: 2 | W14: 18 | X14: 0.41666667 | Y14: Исходная руда №1 | Z14: 0.9 | AA14: =100-Z14 -> 99.1 | AC14: №4 | AD14: 34 | AE14: 12 | AF14: =AE14*11/60 -> 2.2
A15: 19 | P15: 41.6 | Q15: 0 | R15: 0 | S15: 36 | T15: 12.819 | U15: =SUM(P15:T15) -> 90.419 | W15: 19 | Y15: Исходная руда №3 | AA15: =100-Z15 -> 100 | AC15: №5 | AD15: 10 | AE15: 13 | AF15: =AE15*11/60 -> 2.3833333
A16: 20 | P16: 39.8 | Q16: 0 | R16: 0 | S16: 35 | T16: 13.307 | U16: =SUM(P16:T16) -> 88.107 | V16: 2 | W16: 20 | Y16: Исходная руда №4 | Z16: 0.6 | AA16: =100-Z16 -> 99.4 | AE16: 14 | AF16: =AE16*11/60 -> 2.5666667
A17: среднее | B17: =AVERAGE(B5:B15) -> 68 | C17: =AVERAGE(C5:C16) -> 57.5 | D17: =AVERAGE(D5:D15) -> #DIV/0! | E17: =AVERAGE(E5:E15) -> 63 | F17: =AVERAGE(F5:F15) -> 65 | G17: =AVERAGE(G5:G16) -> 44.5 | H17: =AVERAGE(H5:H16) -> 30.5 | I17: =AVERAGE(I5:I15) -> 25 | J17: =AVERAGE(J5:J15) -> 7.5 | K17: =AVERAGE(K5:K15) -> 54 | L17: =AVERAGE(L5:L15) -> #DIV/0! | M17: =AVERAGE(M5:M15) -> 48 | N17: =AVERAGE(N5:N15) -> 51.5 | O17: =AVERAGE(O5:O16) -> 71.5 | P17: =SUM(P5:P16) -> 464 | Q17: =SUM(Q5:Q16) -> 0 | R17: =SUM(R5:R16) -> 0 | S17: =SUM(S5:S16) -> 418 | T17: =SUM(T5:T16) -> 135.516 | U17: =SUM(P17:T17) -> 1017.516 | V17: =SUM(V5:V16) -> 12 | Y17: Исходная руда №5 | Z17: 1.1 | AA17: =100-Z17 -> 98.9 | AB17: 0.54166667 | AC17: №1 | AD17: 41 | AE17: 15 | AF17: =AE17*11/60 -> 2.75
AA18: 99.13 | AC18: №3 | AE18: 16 | AF18: =AE18*11/60 -> 2.9333333
A19: Загрузка шаров мельниц | C19: Ø, мм | D19: тн | F19: Примечание | I19: Ситовый анализ 02.01.26 см 1 | M19: Влага руды, % | P19: 2.1 | S19: 2 | T19: 2.3 | U19: =(U17-U20)/U17*100 -> 2.0855562 | X19: 0.5 | AA19: - | AC19: №4 | AD19: 34 | AE19: 17 | AF19: =AE19*11/60 -> 3.1166667
A20: №1 | C20: 60 | D20: 0.15 | F20: новые | K20: % | M20: Итого СМТ по весам за смену | P20: =(P17-(P17*P19/100)) -> 454.256 | R20: =(R17-(R17*R19/100)) -> 0 | S20: =(S17-(S17*S19/100)) -> 409.64 | T20: =(T17-(T17*T19/100)) -> 132.39913 | U20: =P20+Q20+R20+S20+T20 -> 996.29513 | Y20: Исходная руда №1 | Z20: 0.2 | AA20: =100-Z20 -> 99.8 | AC20: №5 | AD20: 10 | AE20: 18 | AF20: =AE20*11/60 -> 3.3
A21: №2 | C21: 30 | D21: 0.15 | F21: новые | I21: ГЦ№1 | J21: 49 | M21: Итого СМТ замер за смену | P21: =(U17-(U17*U19/100)) -> 996.29513 | Y21: Исходная руда №3 | AA21: =100-Z21 -> 100 | AE21: 19 | AF21: =AE21*11/60 -> 3.4833333
A22: №4 | C22: 60 | D22: 0.15 | F22: новые | I22: 100 | J22: =I22-J21 -> 51 | K22: =J22/I22*100 -> 51 | Y22: Исходная руда №4 | Z22: 0.2 | AA22: =100-Z22 -> 99.8 | AB22: 0.625 | AC22: №1 | AD22: 42 | AE22: 20 | AF22: =AE22*11/60 -> 3.6666667
A23: №5 | C23: 60 | D23: 0.15 | F23: новые | I23: ГЦ№2 | J23: 28 | M23: Итого за сутки: | Y23: Исходная руда №5 | Z23: 0.3 | AA23: =100-Z23 -> 99.7 | AC23: №3 | AE23: 21 | AF23: =AE23*11/60 -> 3.85
I24: 100 | J24: =I24-J23 -> 72 | K24: =J24/I24*100 -> 72 | M24: Итого с начала месяца: | AA24: 99.76 | AC24: №4 | AD24: 35 | AE24: 22 | AF24: =AE24*11/60 -> 4.0333333
X25: 0.625 | AA25: - | AC25: №5 | AD25: 10 | AE25: 23 | AF25: =AE25*11/60 -> 4.2166667
Y26: Исходная руда №1 | Z26: 0.3 | AA26: =100-Z26 -> 99.7 | AE26: 24 | AF26: =AE26*11/60 -> 4.4
A27: Простой мельниц | C27: с | D27: до | F27: кол-во мин | H27: Причины простоя | Y27: Исходная руда №3 | AA27: =100-Z27 -> 100 | AB27: 0.70833333 | AC27: №1 | AD27: 37 | AE27: 25 | AF27: =AE27*11/60 -> 4.5833333
H28: МШР №4 ручной замер - сбой эл счетчика. | Y28: Исходная руда №4 | Z28: 0.6 | AA28: =100-Z28 -> 99.4 | AC28: №3 | AE28: 26 | AF28: =AE28*11/60 -> 4.7666667
A29: №3 | C29: 0.33333333 | D29: 0.83333333 | F29: 12 часов | H29: МШР стоит - ППР. | Y29: Исходная руда №5 | Z29: 0.5 | AA29: =100-Z29 -> 99.5 | AC29: №4 | AD29: 35 | AE29: 27 | AF29: =AE29*11/60 -> 4.95
H30: В 09:36 - 09:48 остановили питание МШР №1 - перегруз.12мин,11:25:11:30. 5мин 15:30 - 15:39. 9мин 16:05-16:16. 11 мин | AA30: 99.53 | AC30: №5 | AD30: 10 | AE30: 28 | AF30: =AE30*11/60 -> 5.1333333
H31: В 09:20 перешли на 1 секцию флотации. В 9:30 остановили 2 секцию флотации. | X31: 0.70833333 | AA31: - | AE31: 29 | AF31: =AE31*11/60 -> 5.3166667
Y32: Исходная руда №1 | Z32: 1.2 | AA32: =100-Z32 -> 98.8 | AB32: 0.79166667 | AC32: №1 | AD32: 42 | AE32: 30 | AF32: =AE32*11/60 -> 5.5
Y33: Исходная руда №3 | AA33: =100-Z33 -> 100 | AC33: №3 | AE33: 31 | AF33: =AE33*11/60 -> 5.6833333
Y34: Исходная руда №4 | Z34: 0.7 | AA34: =100-Z34 -> 99.3 | AC34: №4 | AD34: 36 | AE34: 32 | AF34: =AE34*11/60 -> 5.8666667
Y35: Исходная руда №5 | Z35: 0.5 | AA35: =100-Z35 -> 99.5 | AC35: №5 | AD35: 11 | AE35: 33 | AF35: =AE35*11/60 -> 6.05
AA36: =(AA32+AA33+AA34+AA35)/4 -> 99.4 | AE36: 34 | AF36: =AE36*11/60 -> 6.2333333
AE37: 35 | AF37: =AE37*11/60 -> 6.4166667
AE38: 36 | AF38: =AE38*11/60 -> 6.6
AE39: 37 | AF39: =AE39*11/60 -> 6.7833333
A40: Остаток МКР на начало смены | D40: 99 | AE40: 38 | AF40: =AE40*11/60 -> 6.9666667
...

Sheet 03.01.26см1
A1: Дата | B1: 03.01.2026 | F1: Смена | G1: 1 | AE1: Мельница №5
B2: Плотность, % | N2: Ситовой анализ, % -74мкм | P2: Производительность мельниц, тн/ч | U2: все мельницы | V2: Выпуск МКР | W2: Время | X2: на начало смены | Y2: на конец смены | Z2: переработка по счетчику | AA2: № | AB2: Переработка Ручной замер | AE2: мин | AF2: тонн
A3: Время | B3: Слив мельниц | G3: Слив гидроциклона | I3: Сгуститель | K3: Классификатор | N3: Гидроциклон | AA3: МШР | AE3: 1 | AF3: =AE3*40/60 -> 0.66666667
B4: 1 | C4: 2 | D4: 3 | E4: 4 | F4: 5 | G4: 1ст | H4: 2ст | I4: 1 | J4: 2 | K4: 1 | L4: 3 | M4: 5 | N4: 1ст | O4: 2ст | P4: 1 | Q4: 2 | R4: 3 | S4: 4 | T4: 5 | AB4: Время | AC4: Мельница | AD4: Ручной | AE4: 2 | AF4: =AE4*40/60 -> 1.3333333
A5: 21 | P5: 40.8 | Q5: 0 | R5: 0 | S5: 34 | T5: 12.05 | U5: =SUM(P5:T5) -> 86.85 | W5: 21 | X5: ='02.01.26см2'!Y5 -> 512074.7 | Y5: =X5+P17 -> 512574.7 | Z5: =Y5-X5 -> 500 | AA5: 1 | AE5: 3 | AF5: =AE5*40/60 -> 2
A6: 22 | P6: 42.2 | Q6: 0 | R6: 0 | S6: 35 | T6: 13.804 | U6: =SUM(P6:T6) -> 91.004 | V6: 2 | W6: 22 | X6: ='02.01.26см2'!X6 -> 810050.11 | Y6: =X6+R17 -> 810050.11 | Z6: =Y6-X6 -> 0 | AA6: 3 | AE6: 4 | AF6: =AE6*40/60 -> 2.6666667
A7: 23 | P7: 41.2 | Q7: 0 | R7: 0 | S7: 34 | T7: 13.508 | U7: =SUM(P7:T7) -> 88.708 | V7: 3 | W7: 23 | X7: ='02.01.26см2'!Y7 -> 503746 | Y7: ='02.01.26см2'!Y7 -> 503746 | Z7: =Y7-X7 -> 0 | AA7: 4 | AB7: 0.875 | AC7: №1 | AD7: 41 | AE7: 5 | AF7: =AE7*40/60 -> 3.3333333
A8: 24 | B8: 71 | C8: 59 | E8: 65 | F8: 65 | G8: 44 | H8: 27 | K8: 59 | M8: 51 | N8: 56 | O8: 74 | P8: 42.8 | Q8: 0 | R8: 0 | S8: 34 | T8: 13.266 | U8: =SUM(P8:T8) -> 90.066 | V8: 1 | W8: 24 | X8: ='02.01.26см2'!Y8 -> 510.691 | Y8: =X8+T17 -> 667.946 | Z8: =T17 -> 157.255 | AA8: 5 | AC8: №3 | AE8: 6 | AF8: =AE8*40/60 -> 4
A9: 1 | P9: 39.9 | Q9: 0 | R9: 0 | S9: 35 | T9: 12.587 | U9: =SUM(P9:T9) -> 87.487 | W9: 1 | X9: Итого производ - ность за смену | Z9: =SUM(Z5:Z8) -> 657.255 | AC9: №4 | AD9: 34 | AE9: 7 | AF9: =AE9*40/60 -> 4.6666667
A10: 2 | P10: 39.7 | Q10: 0 | R10: 0 | S10: 33 | T10: 12.597 | U10: =SUM(P10:T10) -> 85.297 | V10: 1 | W10: 2 | AC10: №5 | AD10: 11 | AE10: 8 | AF10: =AE10*40/60 -> 5.3333333
A11: 3 | P11: 43.9 | Q11: 0 | R11: 0 | S11: 34 | T11: 13.326 | U11: =SUM(P11:T11) -> 91.226 | V11: 1 | W11: 3 | X11: Руда с конвейера Сито 12 мм | AE11: 9 | AF11: =AE11*40/60 -> 6
A12: 4 | P12: 41.7 | Q12: 0 | R12: 0 | S12: 35 | T12: 13.441 | U12: =SUM(P12:T12) -> 90.141 | V12: 1 | W12: 4 | AB12: 0.95833333 | AC12: №1 | AD12: 40 | AE12: 10 | AF12: =AE12*40/60 -> 6.6666667
A13: 5 | B13: 68 | C13: 61 | E13: 69 | F13: 67 | G13: 48 | H13: 33 | K13: 59 | M13: 54 | N13: 50 | O13: 72 | P13: 40.7 | Q13: 0 | R13: 0 | S13: 34 | T13: 12.644 | U13: =SUM(P13:T13) -> 87.344 | V13: 1 | W13: 5 | X13: Время | Y13: Мельница | Z13: + | AA13: - | AC13: №3 | AE13: 11 | AF13: =AE13*40/60 -> 7.3333333
A14: 6 | P14: 42.6 | Q14: 0 | R14: 0 | S14: 35 | T14: 12.462 | U14: =SUM(P14:T14) -> 90.062 | V14: 1 | W14: 6 | X14: 0.91666667 | Y14: Исходная руда №1 | Z14: 1 | AA14: =100-Z14 -> 99 | AC14: №4 | AD14: 34 | AE14: 12 | AF14: =AE14*40/60 -> 8
A15: 7 | P15: 43.6 | Q15: 0 | R15: 0 | S15: 33 | T15: 14.099 | U15: =SUM(P15:T15) -> 90.699 | V15: 1 | W15: 7 | Y15: Исходная руда №3 | AA15: =100-Z15 -> 100 | AC15: №5 | AD15: 12 | AE15: 13 | AF15: =AE15*40/60 -> 8.6666667
A16: 8 | P16: 40.9 | Q16: 0 | R16: 0 | S16: 33 | T16: 13.471 | U16: =SUM(P16:T16) -> 87.371 | V16: 1 | W16: 8 | Y16: Исходная руда №4 | Z16: 0.7 | AA16: =100-Z16 -> 99.3 | AE16: 14 | AF16: =AE16*40/60 -> 9.3333333
A17: среднее | B17: =AVERAGE(B5:B15) -> 69.5 | C17: =AVERAGE(C5:C16) -> 60 | D17: =AVERAGE(D5:D15) -> #DIV/0! | E17: =AVERAGE(E5:E15) -> 67 | F17: =AVERAGE(F5:F15) -> 66 | G17: =AVERAGE(G5:G16) -> 46 | H17: =AVERAGE(H5:H16) -> 30 | I17: =AVERAGE(I5:I15) -> #DIV/0! | J17: =AVERAGE(J5:J15) -> #DIV/0! | K17: =AVERAGE(K5:K15) -> 59 | L17: =AVERAGE(L5:L15) -> #DIV/0! | M17: =AVERAGE(M5:M15) -> 52.5 | N17: =AVERAGE(N5:N15) -> 53 | O17: =AVERAGE(O5:O16) -> 73 | P17: =SUM(P5:P16) -> 500 | Q17: =SUM(Q5:Q16) -> 0 | R17: =SUM(R5:R16) -> 0 | S17: =SUM(S5:S16) -> 409 | T17: =SUM(T5:T16) -> 157.255 | U17: =SUM(P17:T17) -> 1066.255 | V17: =SUM(V5:V16) -> 13 | Y17: Исходная руда №5 | Z17: 0.9 | AA17: =100-Z17 -> 99.1 | AB17: 0.041666667 | AC17: №1 | AD17: 40 | AE17: 15 | AF17: =AE17*40/60 -> 10
AA18: =(AA14+AA16+AA17)/3 -> 99.133333 | AC18: №3 | AE18: 16 | AF18: =AE18*40/60 -> 10.666667
A19: Загрузка шаров мельниц | C19: Ø, мм | D19: тн | F19: Примечание | I19: Ситовый анализ 02.01.26 см 2 | M19: Влага руды, % | P19: 2.6 | S19: 2.5 | T19: 2.2 | U19: =(U17-U20)/U17*100 -> 2.5026481 | X19: 0.041666667 | AA19: - | AC19: №4 | AD19: 35 | AE19: 17 | AF19: =AE19*40/60 -> 11.333333
A20: №1 | C20: 60 | D20: 0.2 | F20: новые | K20: % | M20: Итого СМТ по весам за смену | P20: =(P17-(P17*P19/100)) -> 487 | R20: =(R17-(R17*R19/100)) -> 0 | S20: =(S17-(S17*S19/100)) -> 398.775 | T20: =(T17-(T17*T19/100)) -> 153.79539 | U20: =P20+Q20+R20+S20+T20 -> 1039.5704 | Y20: Исходная руда №1 | Z20: 1.6 | AA20: =100-Z20 -> 98.4 | AC20: №5 | AD20: 11 | AE20: 18 | AF20: =AE20*40/60 -> 12
A21: №4 | C21: 60 | D21: 0.2 | F21: новые | I21: ГЦ№1 | J21: 50 | M21: Итого СМТ замер за смену | P21: =(U17-(U17*U19/100)) -> 1039.5704 | Y21: Исходная руда №3 | AA21: =100-Z21 -> 100 | AE21: 19 | AF21: =AE21*40/60 -> 12.666667
A22: №5 | C22: 60 | D22: 0.1 | F22: новые | I22: 100 | J22: =I22-J21 -> 50 | K22: =J22/I22*100 -> 50 | Y22: Исходная руда №4 | Z22: 1.3 | AA22: =100-Z22 -> 98.7 | AB22: 0.125 | AC22: №1 | AD22: 42 | AE22: 20 | AF22: =AE22*40/60 -> 13.333333
I23: ГЦ№2 | J23: 29 | M23: Итого за сутки: | Y23: Исходная руда №5 | Z23: 1.5 | AA23: =100-Z23 -> 98.5 | AC23: №3 | AE23: 21 | AF23: =AE23*40/60 -> 14
I24: 100 | J24: =I24-J23 -> 71 | K24: =J24/I24*100 -> 71 | M24: Итого с начала месяца: | AA24: =(AA20+AA22+AA23)/3 -> 98.533333 | AC24: №4 | AD24: 34 | AE24: 22 | AF24: =AE24*40/60 -> 14.666667
X25: 0.125 | AA25: - | AC25: №5 | AD25: 12 | AE25: 23 | AF25: =AE25*40/60 -> 15.333333
Y26: Исходная руда №1 | Z26: 0.9 | AA26: =100-Z26 -> 99.1 | AE26: 24 | AF26: =AE26*40/60 -> 16
A27: Простой мельниц | C27: с | D27: до | F27: кол-во мин | H27: Причины простоя | Y27: Исходная руда №3 | AA27: =100-Z27 -> 100 | AB27: 0.20833333 | AC27: №1 | AD27: 40 | AE27: 25 | AF27: =AE27*40/60 -> 16.666667
H28: МШР №4 ручной замер - сбой эл счетчика. | Y28: Исходная руда №4 | Z28: 1 | AA28: =100-Z28 -> 99 | AC28: №3 | AE28: 26 | AF28: =AE28*40/60 -> 17.333333
A29: №3 | C29: 0.83333333 | D29: 0.33333333 | F29: 12 часов | H29: МШР стоит - ППР. | Y29: Исходная руда №5 | Z29: 1.2 | AA29: =100-Z29 -> 98.8 | AC29: №4 | AD29: 34 | AE29: 27 | AF29: =AE29*40/60 -> 18
AA30: =(AA26+AA28+AA29)/3 -> 98.966667 | AC30: №5 | AD30: 11 | AE30: 28 | AF30: =AE30*40/60 -> 18.666667
X31: 0.20833333 | AA31: - | AE31: 29 | AF31: =AE31*40/60 -> 19.333333
Y32: Исходная руда №1 | Z32: 0.6 | AA32: =100-Z32 -> 99.4 | AB32: 0.29166667 | AC32: №1 | AD32: 40 | AE32: 30 | AF32: =AE32*40/60 -> 20
Y33: Исходная руда №3 | AA33: =100-Z33 -> 100 | AC33: №3 | AE33: 31 | AF33: =AE33*40/60 -> 20.666667
Y34: Исходная руда №4 | Z34: 1.3 | AA34: =100-Z34 -> 98.7 | AC34: №4 | AD34: 33 | AE34: 32 | AF34: =AE34*40/60 -> 21.333333
Y35: Исходная руда №5 | Z35: 0.4 | AA35: =100-Z35 -> 99.6 | AC35: №5 | AD35: 12 | AE35: 33 | AF35: =AE35*40/60 -> 22
AA36: =(AA32+AA34+AA35)/3 -> 99.233333 | AE36: 34 | AF36: =AE36*40/60 -> 22.666667
AE37: 35 | AF37: =AE37*40/60 -> 23.333333
AE38: 36 | AF38: =AE38*40/60 -> 24
AE39: 37 | AF39: =AE39*40/60 -> 24.666667
A40: Остаток МКР на начало смены | D40: 55 | AE40: 38 | AF40: =AE40*40/60 -> 25.333333
...

Sheet 03.01.26см2
A1: Дата | B1: 03.01.2026 | F1: Смена | G1: 2 | AE1: Мельница №5
B2: Плотность, % | N2: Ситовой анализ, % -74мкм | P2: Производительность мельниц, тн/ч | U2: все мельницы | V2: Выпуск МКР | W2: Время | X2: на начало смены | Y2: на конец смены | Z2: переработка по счетчику | AA2: № | AB2: Переработка Ручной замер | AE2: мин | AF2: тонн
A3: Время | B3: Слив мельниц | G3: Слив гидроциклона | I3: Сгуститель | K3: Классификатор | N3: Гидроциклон | AA3: МШР | AE3: 1 | AF3: =AE3*11/60 -> 0.18333333
B4: 1 | C4: 2 | D4: 3 | E4: 4 | F4: 5 | G4: 1ст | H4: 2ст | I4: 1 | J4: 2 | K4: 1 | L4: 3 | M4: 5 | N4: 1ст | O4: 2ст | P4: 1 | Q4: 2 | R4: 3 | S4: 4 | T4: 5 | AB4: Время | AC4: Мельница | AD4: Ручной | AE4: 2 | AF4: =AE4*11/60 -> 0.36666667
A5: 9 | P5: 42 | Q5: 0 | R5: 0 | S5: 34 | T5: 13.513 | U5: =SUM(P5:T5) -> 89.513 | W5: 9 | X5: 512574.7 | Y5: =X5+P17 -> 513065.5 | Z5: =Y5-X5 -> 490.8 | AA5: 1 | AE5: 3 | AF5: =AE5*11/60 -> 0.55
A6: 10 | P6: 42.9 | Q6: 0 | R6: 0 | S6: 35 | T6: 13.638 | U6: =SUM(P6:T6) -> 91.538 | V6: 1 | W6: 10 | X6: 810050.11 | Y6: =X6+R17 -> 810199.56 | Z6: =Y6-X6 -> 149.451 | AA6: 3 | AE6: 4 | AF6: =AE6*11/60 -> 0.73333333
A7: 11 | B7: 66 | C7: 63 | E7: 62 | F7: 62 | G7: 44 | H7: 33 | I7: 16 | J7: 0 | K7: 54 | M7: 47 | N7: 55 | O7: 72 | P7: 42 | Q7: 0 | R7: 0 | S7: 33 | T7: 13.462 | U7: =SUM(P7:T7) -> 88.462 | V7: 1 | W7: 11 | X7: 503746 | Y7: =X7+S17 -> 504121 | Z7: =Y7-X7 -> 375 | AA7: 4 | AB7: 0.375 | AC7: №1 | AD7: 42 | AE7: 5 | AF7: =AE7*11/60 -> 0.91666667
A8: 12 | P8: 40.7 | Q8: 0 | R8: 0 | S8: 34 | T8: 13.195 | U8: =SUM(P8:T8) -> 87.895 | V8: 1 | W8: 12 | X8: 667.946 | Y8: =X8+T17 -> 824.758 | Z8: =T17 -> 156.812 | AA8: 5 | AC8: №3 | AE8: 6 | AF8: =AE8*11/60 -> 1.1
A9: 13 | P9: 40.1 | Q9: 0 | R9: 0 | S9: 32 | T9: 12.974 | U9: =SUM(P9:T9) -> 85.074 | W9: 13 | X9: Итого производ - ность за смену | Z9: =SUM(Z5:Z8) -> 1172.063 | AC9: №4 | AD9: 34 | AE9: 7 | AF9: =AE9*11/60 -> 1.2833333
A10: 14 | P10: 39.8 | Q10: 0 | R10: 0 | S10: 33 | T10: 12.429 | U10: =SUM(P10:T10) -> 85.229 | W10: 14 | AC10: №5 | AD10: 11 | AE10: 8 | AF10: =AE10*11/60 -> 1.4666667
A11: 15 | P11: 40.7 | Q11: 0 | R11: 0 | S11: 33 | T11: 12.18 | U11: =SUM(P11:T11) -> 85.88 | V11: 1 | W11: 15 | X11: Руда с конвейера Сито 12 мм | AE11: 9 | AF11: =AE11*11/60 -> 1.65
A12: 16 | P12: 40 | Q12: 0 | R12: 0 | S12: 32 | T12: 12.903 | U12: =SUM(P12:T12) -> 84.903 | V12: 3 | W12: 16 | AB12: 0.45833333 | AC12: №1 | AD12: 41 | AE12: 10 | AF12: =AE12*11/60 -> 1.8333333
A13: 17 | B13: 62 | C13: 58 | E13: 56 | F13: 61 | G13: 46 | H13: 28 | I13: 13 | K13: 45 | M13: 38 | N13: 51 | O13: 76 | P13: 40.9 | Q13: 0 | R13: 20.999 | S13: 23 | T13: 13.266 | U13: =SUM(P13:T13) -> 98.165 | V13: 2 | W13: 17 | X13: Время | Y13: Мельница | Z13: + | AA13: - | AC13: №3 | AE13: 11 | AF13: =AE13*11/60 -> 2.0166667
A14: 18 | P14: 39.6 | Q14: 0 | R14: 42.074 | S14: 22 | T14: 13.148 | U14: =SUM(P14:T14) -> 116.822 | V14: 1 | W14: 18 | X14: 0.41666667 | Y14: Исходная руда №1 | Z14: 0.6 | AA14: =100-Z14 -> 99.4 | AC14: №4 | AD14: 33 | AE14: 12 | AF14: =AE14*11/60 -> 2.2
A15: 19 | P15: 40.9 | Q15: 0 | R15: 43.52 | S15: 32 | T15: 12.691 | U15: =SUM(P15:T15) -> 129.111 | V15: 1 | W15: 19 | Y15: Исходная руда №3 | AA15: =100-Z15 -> 100 | AC15: №5 | AD15: 10 | AE15: 13 | AF15: =AE15*11/60 -> 2.3833333
A16: 20 | P16: 41.2 | Q16: 0 | R16: 42.858 | S16: 32 | T16: 13.413 | U16: =SUM(P16:T16) -> 129.471 | V16: 2 | W16: 20 | Y16: Исходная руда №4 | Z16: 0.4 | AA16: =100-Z16 -> 99.6 | AE16: 14 | AF16: =AE16*11/60 -> 2.5666667
A17: среднее | B17: =AVERAGE(B5:B15) -> 64 | C17: =AVERAGE(C5:C16) -> 60.5 | D17: =AVERAGE(D5:D15) -> #DIV/0! | E17: =AVERAGE(E5:E15) -> 59 | F17: =AVERAGE(F5:F15) -> 61.5 | G17: =AVERAGE(G5:G16) -> 45 | H17: =AVERAGE(H5:H16) -> 30.5 | I17: =AVERAGE(I5:I15) -> 14.5 | J17: =AVERAGE(J5:J15) -> 0 | K17: =AVERAGE(K5:K15) -> 49.5 | L17: =AVERAGE(L5:L15) -> #DIV/0! | M17: =AVERAGE(M5:M15) -> 42.5 | N17: =AVERAGE(N5:N15) -> 53 | O17: =AVERAGE(O5:O16) -> 74 | P17: =SUM(P5:P16) -> 490.8 | Q17: =SUM(Q5:Q16) -> 0 | R17: =SUM(R5:R16) -> 149.451 | S17: =SUM(S5:S16) -> 375 | T17: =SUM(T5:T16) -> 156.812 | U17: =SUM(P17:T17) -> 1172.063 | V17: =SUM(V5:V16) -> 13 | Y17: Исходная руда №5 | Z17: 0.8 | AA17: =100-Z17 -> 99.2 | AB17: 0.54166667 | AC17: №1 | AD17: 41 | AE17: 15 | AF17: =AE17*11/60 -> 2.75
AA18: 99.4 | AC18: №3 | AE18: 16 | AF18: =AE18*11/60 -> 2.9333333
A19: Загрузка шаров мельниц | C19: Ø, мм | D19: тн | F19: Примечание | I19: Ситовый анализ 03.01.26 см 1 | M19: Влага руды, % | P19: 2.1 | S19: 1.8 | T19: 1.9 | U19: =(U17-U20)/U17*100 -> 1.7094839 | X19: 0.5 | AA19: - | AC19: №4 | AD19: 32 | AE19: 17 | AF19: =AE19*11/60 -> 3.1166667
A20: №1 | C20: 60 | D20: 0.15 | F20: новые | K20: % | M20: Итого СМТ по весам за смену | P20: =(P17-(P17*P19/100)) -> 480.4932 | R20: =(R17-(R17*R19/100)) -> 149.451 | S20: =(S17-(S17*S19/100)) -> 368.25 | T20: =(T17-(T17*T19/100)) -> 153.83257 | U20: =P20+Q20+R20+S20+T20 -> 1152.0268 | Y20: Исходная руда №1 | Z20: 0.8 | AA20: =100-Z20 -> 99.2 | AC20: №5 | AD20: 10 | AE20: 18 | AF20: =AE20*11/60 -> 3.3
A21: №2 | C21: 30 | D21: 0.15 | F21: новые | I21: ГЦ№1 | J21: 46 | M21: Итого СМТ замер за смену | P21: =(U17-(U17*U19/100)) -> 1152.0268 | Y21: Исходная руда №3 | AA21: =100-Z21 -> 100 | AE21: 19 | AF21: =AE21*11/60 -> 3.4833333
A22: №4 | C22: 60 | D22: 0.15 | F22: новые | I22: 100 | J22: =I22-J21 -> 54 | K22: =J22/I22*100 -> 54 | Y22: Исходная руда №4 | Z22: 0.7 | AA22: =100-Z22 -> 99.3 | AB22: 0.625 | AC22: №1 | AD22: 41 | AE22: 20 | AF22: =AE22*11/60 -> 3.6666667
A23: №5 | C23: 60 | D23: 0.15 | F23: новые | I23: ГЦ№2 | J23: 27 | M23: Итого за сутки: | Y23: Исходная руда №5 | Z23: 0.6 | AA23: =100-Z23 -> 99.4 | AC23: №3 | AE23: 21 | AF23: =AE23*11/60 -> 3.85
I24: 100 | J24: =I24-J23 -> 73 | K24: =J24/I24*100 -> 73 | M24: Итого с начала месяца: | AA24: 99.3 | AC24: №4 | AD24: 33 | AE24: 22 | AF24: =AE24*11/60 -> 4.0333333
X25: 0.625 | AA25: - | AC25: №5 | AD25: 10 | AE25: 23 | AF25: =AE25*11/60 -> 4.2166667
Y26: Исходная руда №1 | Z26: 0.4 | AA26: =100-Z26 -> 99.6 | AE26: 24 | AF26: =AE26*11/60 -> 4.4
A27: Простой мельниц | C27: с | D27: до | F27: кол-во мин | H27: Причины простоя | Y27: Исходная руда №3 | AA27: =100-Z27 -> 100 | AB27: 0.70833333 | AC27: №1 | AD27: 43 | AE27: 25 | AF27: =AE27*11/60 -> 4.5833333
H28: МШР №4 ручной замер - сбой эл счетчика. | Y28: Исходная руда №4 | Z28: 0.6 | AA28: =100-Z28 -> 99.4 | AC28: №3 | AD28: 39 | AE28: 26 | AF28: =AE28*11/60 -> 4.7666667
A29: №3 | C29: 0.33333333 | D29: 0.68402778 | F29: 8 часов 25 мин | H29: МШР стоит - ППР. | Y29: Исходная руда №5 | Z29: 0.9 | AA29: =100-Z29 -> 99.1 | AC29: №4 | AD29: 33 | AE29: 27 | AF29: =AE29*11/60 -> 4.95
A30: №4 | C30: 0.69513889 | D30: 0.71736111 | F30: 32 мин | H30: Остановили МШР №4 по мех части - подтяжка анкерных болтов | AA30: 99.37 | AC30: №5 | AD30: 11 | AE30: 28 | AF30: =AE30*11/60 -> 5.1333333
X31: 0.70833333 | AA31: - | AE31: 29 | AF31: =AE31*11/60 -> 5.3166667
Y32: Исходная руда №1 | Z32: 0.2 | AA32: =100-Z32 -> 99.8 | AB32: 0.79166667 | AC32: №1 | AD32: 41 | AE32: 30 | AF32: =AE32*11/60 -> 5.5
Y33: Исходная руда №3 | Z33: 0.6 | AA33: =100-Z33 -> 99.4 | AC33: №3 | AD33: 42 | AE33: 31 | AF33: =AE33*11/60 -> 5.6833333
Y34: Исходная руда №4 | Z34: 0.3 | AA34: =100-Z34 -> 99.7 | AC34: №4 | AD34: 32 | AE34: 32 | AF34: =AE34*11/60 -> 5.8666667
Y35: Исходная руда №5 | Z35: 0.7 | AA35: =100-Z35 -> 99.3 | AC35: №5 | AD35: 11 | AE35: 33 | AF35: =AE35*11/60 -> 6.05
AA36: =(AA32+AA33+AA34+AA35)/4 -> 99.55 | AE36: 34 | AF36: =AE36*11/60 -> 6.2333333
AE37: 35 | AF37: =AE37*11/60 -> 6.4166667
AE38: 36 | AF38: =AE38*11/60 -> 6.6
AE39: 37 | AF39: =AE39*11/60 -> 6.7833333
A40: Остаток МКР на начало смены | D40: 68 | AE40: 38 | AF40: =AE40*11/60 -> 6.9666667
...

Sheet 04.01.26см1
A1: Дата | B1: 04.01.2026 | F1: Смена | G1: 1 | AE1: Мельница №5
B2: Плотность, % | N2: Ситовой анализ, % -74мкм | P2: Производительность мельниц, тн/ч | U2: все мельницы | V2: Выпуск МКР | W2: Время | X2: на начало смены | Y2: на конец смены | Z2: переработка по счетчику | AA2: № | AB2: Переработка Ручной замер | AE2: мин | AF2: тонн
A3: Время | B3: Слив мельниц | G3: Слив гидроциклона | I3: Сгуститель | K3: Классификатор | N3: Гидроциклон | AA3: МШР | AE3: 1 | AF3: =AE3*40/60 -> 0.66666667
B4: 1 | C4: 2 | D4: 3 | E4: 4 | F4: 5 | G4: 1ст | H4: 2ст | I4: 1 | J4: 2 | K4: 1 | L4: 3 | M4: 5 | N4: 1ст | O4: 2ст | P4: 1 | Q4: 2 | R4: 3 | S4: 4 | T4: 5 | AB4: Время | AC4: Мельница | AD4: Ручной | AE4: 2 | AF4: =AE4*40/60 -> 1.3333333
A5: 21 | P5: 40.7 | Q5: 0 | R5: 40.107 | S5: 33 | T5: 13.009 | U5: =SUM(P5:T5) -> 126.816 | W5: 21 | X5: ='03.01.26см2'!Y5 -> 513065.5 | Y5: =X5+P17 -> 513560.9 | Z5: =Y5-X5 -> 495.4 | AA5: 1 | AE5: 3 | AF5: =AE5*40/60 -> 2
A6: 22 | P6: 40.9 | Q6: 0 | R6: 36.045 | S6: 32 | T6: 13.245 | U6: =SUM(P6:T6) -> 122.19 | V6: 1 | W6: 22 | X6: ='03.01.26см2'!Y6 -> 810199.56 | Y6: =X6+R17 -> 810665.05 | Z6: =Y6-X6 -> 465.485 | AA6: 3 | AE6: 4 | AF6: =AE6*40/60 -> 2.6666667
A7: 23 | P7: 39.9 | Q7: 0 | R7: 40.134 | S7: 32 | T7: 12.913 | U7: =SUM(P7:T7) -> 124.947 | W7: 23 | X7: ='03.01.26см2'!Y7 -> 504121 | Y7: =X7+S17 -> 504517 | Z7: =Y7-X7 -> 396 | AA7: 4 | AB7: 0.875 | AC7: №1 | AD7: 41 | AE7: 5 | AF7: =AE7*40/60 -> 3.3333333
A8: 24 | B8: 69 | C8: 65 | D8: 73 | E8: 64 | F8: 59 | G8: 48 | H8: 40 | K8: 56 | L8: 58 | M8: 44 | N8: 50 | O8: 64 | P8: 40.8 | Q8: 0 | R8: 38.588 | S8: 33 | T8: 12.994 | U8: =SUM(P8:T8) -> 125.382 | V8: 3 | W8: 24 | X8: ='03.01.26см2'!Y8 -> 824.758 | Y8: =X8+T17 -> 978 | Z8: =T17 -> 153.242 | AA8: 5 | AC8: №3 | AD8: 40 | AE8: 6 | AF8: =AE8*40/60 -> 4
A9: 1 | P9: 41.8 | Q9: 0 | R9: 43.525 | S9: 34 | T9: 12.837 | U9: =SUM(P9:T9) -> 132.162 | V9: 3 | W9: 1 | X9: Итого производ - ность за смену | Z9: =SUM(Z5:Z8) -> 1510.127 | AC9: №4 | AD9: 33 | AE9: 7 | AF9: =AE9*40/60 -> 4.6666667
A10: 2 | P10: 40.6 | Q10: 0 | R10: 42.045 | S10: 33 | T10: 12.796 | U10: =SUM(P10:T10) -> 128.441 | V10: 2 | W10: 2 | AC10: №5 | AD10: 12 | AE10: 8 | AF10: =AE10*40/60 -> 5.3333333
A11: 3 | P11: 40.8 | Q11: 0 | R11: 41.041 | S11: 33 | T11: 12.8 | U11: =SUM(P11:T11) -> 127.641 | W11: 3 | X11: Руда с конвейера Сито 12 мм | AE11: 9 | AF11: =AE11*40/60 -> 6
A12: 4 | P12: 40.7 | Q12: 0 | R12: 43.139 | S12: 34 | T12: 12.363 | U12: =SUM(P12:T12) -> 130.202 | V12: 3 | W12: 4 | AB12: 0.95833333 | AC12: №1 | AD12: 40 | AE12: 10 | AF12: =AE12*40/60 -> 6.6666667
A13: 5 | B13: 68 | C13: 65 | D13: 74 | E13: 62 | F13: 57 | G13: 45 | H13: 40 | K13: 55 | L13: 58 | M13: 49 | N13: 47 | O13: 65 | P13: 42 | Q13: 0 | R13: 42.364 | S13: 34 | T13: 12.224 | U13: =SUM(P13:T13) -> 130.588 | V13: 1 | W13: 5 | X13: Время | Y13: Мельница | Z13: + | AA13: - | AC13: №3 | AD13: 41 | AE13: 11 | AF13: =AE13*40/60 -> 7.3333333
A14: 6 | P14: 42.5 | Q14: 0 | R14: 43.082 | S14: 33 | T14: 12.566 | U14: =SUM(P14:T14) -> 131.148 | V14: 2 | W14: 6 | X14: 0.91666667 | Y14: Исходная руда №1 | Z14: 0.7 | AA14: =100-Z14 -> 99.3 | AC14: №4 | AD14: 32 | AE14: 12 | AF14: =AE14*40/60 -> 8
A15: 7 | P15: 43.3 | Q15: 0 | R15: 42.611 | S15: 34 | T15: 12.846 | U15: =SUM(P15:T15) -> 132.757 | V15: 2 | W15: 7 | Y15: Исходная руда №3 | Z15: 0.9 | AA15: =100-Z15 -> 99.1 | AC15: №5 | AD15: 11 | AE15: 13 | AF15: =AE15*40/60 -> 8.6666667
A16: 8 | P16: 41.4 | Q16: 0 | R16: 12.804 | S16: 31 | T16: 12.649 | U16: =SUM(P16:T16) -> 97.853 | V16: 1 | W16: 8 | Y16: Исходная руда №4 | Z16: 0.4 | AA16: =100-Z16 -> 99.6 | AE16: 14 | AF16: =AE16*40/60 -> 9.3333333
A17: среднее | B17: =AVERAGE(B5:B15) -> 68.5 | C17: =AVERAGE(C5:C16) -> 65 | D17: =AVERAGE(D5:D15) -> 73.5 | E17: =AVERAGE(E5:E15) -> 63 | F17: =AVERAGE(F5:F15) -> 58 | G17: =AVERAGE(G5:G16) -> 46.5 | H17: =AVERAGE(H5:H16) -> 40 | I17: =AVERAGE(I5:I15) -> #DIV/0! | J17: =AVERAGE(J5:J15) -> #DIV/0! | K17: =AVERAGE(K5:K15) -> 55.5 | L17: =AVERAGE(L5:L15) -> 58 | M17: =AVERAGE(M5:M15) -> 46.5 | N17: =AVERAGE(N5:N15) -> 48.5 | O17: =AVERAGE(O5:O16) -> 64.5 | P17: =SUM(P5:P16) -> 495.4 | Q17: =SUM(Q5:Q16) -> 0 | R17: =SUM(R5:R16) -> 465.485 | S17: =SUM(S5:S16) -> 396 | T17: =SUM(T5:T16) -> 153.242 | U17: =SUM(P17:T17) -> 1510.127 | V17: =SUM(V5:V16) -> 18 | Y17: Исходная руда №5 | Z17: 0.8 | AA17: =100-Z17 -> 99.2 | AB17: 0.041666667 | AC17: №1 | AD17: 41 | AE17: 15 | AF17: =AE17*40/60 -> 10
AA18: =(AA14+AA15+AA16+AA17)/4 -> 99.3 | AC18: №3 | AD18: 42 | AE18: 16 | AF18: =AE18*40/60 -> 10.666667
A19: Загрузка шаров мельниц | C19: Ø, мм | D19: тн | F19: Примечание | I19: Ситовый анализ 03.01.26 см 2 | M19: Влага руды, % | P19: 2.3 | R19: 2.4 | S19: 1.8 | T19: 2.5 | U19: =(U17-U20)/U17*100 -> 2.2200047 | X19: 0.041666667 | AA19: - | AC19: №4 | AD19: 34 | AE19: 17 | AF19: =AE19*40/60 -> 11.333333
A20: №1 | C20: 60 | D20: 0.15 | F20: новые | K20: % | M20: Итого СМТ по весам за смену | P20: =(P17-(P17*P19/100)) -> 484.0058 | R20: =(R17-(R17*R19/100)) -> 454.31336 | S20: =(S17-(S17*S19/100)) -> 388.872 | T20: =(T17-(T17*T19/100)) -> 149.41095 | U20: =P20+Q20+R20+S20+T20 -> 1476.6021 | Y20: Исходная руда №1 | Z20: 0.4 | AA20: =100-Z20 -> 99.6 | AC20: №5 | AD20: 11 | AE20: 18 | AF20: =AE20*40/60 -> 12
A21: №2 | C21: 30 | D21: 0.15 | F21: новые | I21: ГЦ№1 | J21: 48 | M21: Итого СМТ замер за смену | P21: =(U17-(U17*U19/100)) -> 1476.6021 | Y21: Исходная руда №3 | Z21: 0.7 | AA21: =100-Z21 -> 99.3 | AE21: 19 | AF21: =AE21*40/60 -> 12.666667
A22: №3 | C22: 60 | D22: 0.15 | F22: новые | I22: 100 | J22: =I22-J21 -> 52 | K22: =J22/I22*100 -> 52 | Y22: Исходная руда №4 | Z22: 0.5 | AA22: =100-Z22 -> 99.5 | AB22: 0.125 | AC22: №1 | AD22: 41 | AE22: 20 | AF22: =AE22*40/60 -> 13.333333
A23: №4 | C23: 60 | D23: 0.1 | F23: новые | I23: ГЦ№2 | J23: 25 | M23: Итого за сутки: | Y23: Исходная руда №5 | Z23: 0.3 | AA23: =100-Z23 -> 99.7 | AC23: №3 | AD23: 42 | AE23: 21 | AF23: =AE23*40/60 -> 14
A24: №5 | C24: 60 | D24: 0.1 | F24: новые | I24: 100 | J24: =I24-J23 -> 75 | K24: =J24/I24*100 -> 75 | M24: Итого с начала месяца: | AA24: =(AA20+AA21+AA22+AA23)/4 -> 99.525 | AC24: №4 | AD24: 33 | AE24: 22 | AF24: =AE24*40/60 -> 14.666667
X25: 0.125 | AA25: - | AC25: №5 | AD25: 11 | AE25: 23 | AF25: =AE25*40/60 -> 15.333333
Y26: Исходная руда №1 | Z26: 0.6 | AA26: =100-Z26 -> 99.4 | AE26: 24 | AF26: =AE26*40/60 -> 16
A27: Простой мельниц | C27: с | D27: до | F27: кол-во мин | H27: Причины простоя | Y27: Исходная руда №3 | Z27: 0.4 | AA27: =100-Z27 -> 99.6 | AB27: 0.20833333 | AC27: №1 | AD27: 41 | AE27: 25 | AF27: =AE27*40/60 -> 16.666667
H28: МШР №4 ручной замер - сбой эл счетчика. | Y28: Исходная руда №4 | Z28: 0.7 | AA28: =100-Z28 -> 99.3 | AC28: №3 | AD28: 41 | AE28: 26 | AF28: =AE28*40/60 -> 17.333333
H29: В 21:10 - 21:20 остановка питание на ленте №17 МШР №3 - забился песковый насадка 10мин | Y29: Исходная руда №5 | Z29: 0.5 | AA29: =100-Z29 -> 99.5 | AC29: №4 | AD29: 34 | AE29: 27 | AF29: =AE29*40/60 -> 18
A30: №3 | C30: 0.29861111 | D30: 0.33333333 | F30: 50 мин | H30: Самопроизвольная остановка мельницы | AA30: =(AA26+AA27+AA28+AA29)/4 -> 99.45 | AC30: №5 | AD30: 11 | AE30: 28 | AF30: =AE30*40/60 -> 18.666667
X31: 0.20833333 | AA31: - | AE31: 29 | AF31: =AE31*40/60 -> 19.333333
Y32: Исходная руда №1 | Z32: 0.4 | AA32: =100-Z32 -> 99.6 | AB32: 0.29166667 | AC32: №1 | AD32: 42 | AE32: 30 | AF32: =AE32*40/60 -> 20
Y33: Исходная руда №3 | Z33: 0.2 | AA33: =100-Z33 -> 99.8 | AC33: №3 | AD33: 41 | AE33: 31 | AF33: =AE33*40/60 -> 20.666667
Y34: Исходная руда №4 | Z34: 0.6 | AA34: =100-Z34 -> 99.4 | AC34: №4 | AD34: 34 | AE34: 32 | AF34: =AE34*40/60 -> 21.333333
Y35: Исходная руда №5 | Z35: 0.2 | AA35: =100-Z35 -> 99.8 | AC35: №5 | AD35: 12 | AE35: 33 | AF35: =AE35*40/60 -> 22
AA36: =(AA32+AA33+AA34+AA35)/4 -> 99.65 | AE36: 34 | AF36: =AE36*40/60 -> 22.666667
AE37: 35 | AF37: =AE37*40/60 -> 23.333333
AE38: 36 | AF38: =AE38*40/60 -> 24
AE39: 37 | AF39: =AE39*40/60 -> 24.666667
A40: Остаток МКР на начало смены | D40: 9 | AE40: 38 | AF40: =AE40*40/60 -> 25.333333
...

Sheet 04.01.26см2
A1: Дата | B1: 04.01.2026 | F1: Смена | G1: 2 | AE1: Мельница №5
B2: Плотность, % | N2: Ситовой анализ, % -74мкм | P2: Производительность мельниц, тн/ч | U2: все мельницы | V2: Выпуск МКР | W2: Время | X2: на начало смены | Y2: на конец смены | Z2: переработка по счетчику | AA2: № | AB2: Переработка Ручной замер | AE2: мин | AF2: тонн
A3: Время | B3: Слив мельниц | G3: Слив гидроциклона | I3: Сгуститель | K3: Классификатор | N3: Гидроциклон | AA3: МШР | AE3: 1 | AF3: =AE3*11/60 -> 0.18333333
B4: 1 | C4: 2 | D4: 3 | E4: 4 | F4: 5 | G4: 1ст | H4: 2ст | I4: 1 | J4: 2 | K4: 1 | L4: 3 | M4: 5 | N4: 1ст | O4: 2ст | P4: 1 | Q4: 2 | R4: 3 | S4: 4 | T4: 5 | AB4: Время | AC4: Мельница | AD4: Ручной | AE4: 2 | AF4: =AE4*11/60 -> 0.36666667
A5: 9 | P5: 39.3 | Q5: 0 | R5: 0 | S5: 17 | T5: 12.013 | U5: =SUM(P5:T5) -> 68.313 | W5: 9 | X5: 513560.9 | Y5: =X5+P17 -> 513924.2 | Z5: =Y5-X5 -> 363.3 | AA5: 1 | AE5: 3 | AF5: =AE5*11/60 -> 0.55
A6: 10 | P6: 39.9 | Q6: 0 | R6: 0 | S6: 0 | T6: 12.357 | U6: =SUM(P6:T6) -> 52.257 | V6: 2 | W6: 10 | X6: 810665.05 | Y6: =X6+R17 -> 811041.54 | Z6: =Y6-X6 -> 376.492 | AA6: 3 | AE6: 4 | AF6: =AE6*11/60 -> 0.73333333
A7: 11 | B7: 65 | C7: 50 | F7: 58 | G7: 39 | H7: 33 | I7: 0 | K7: 49 | M7: 51 | N7: 58 | O7: 70 | P7: 39.5 | Q7: 0 | R7: 0 | S7: 0 | T7: 12.56 | U7: =SUM(P7:T7) -> 52.06 | V7: 1 | W7: 11 | X7: 504517 | Y7: =X7+S17 -> 504781 | Z7: =Y7-X7 -> 264 | AA7: 4 | AB7: 0.375 | AC7: №1 | AD7: 41 | AE7: 5 | AF7: =AE7*11/60 -> 0.91666667
A8: 12 | P8: 37.8 | Q8: 0 | R8: 31.282 | S8: 0 | T8: 12.62 | U8: =SUM(P8:T8) -> 81.702 | V8: 1 | W8: 12 | X8: 978 | Y8: =X8+T17 -> 1131.94 | Z8: =T17 -> 153.94 | AA8: 5 | AC8: №3 | AE8: 6 | AF8: =AE8*11/60 -> 1.1
A9: 13 | D9: 72 | L9: 53 | P9: 41 | Q9: 0 | R9: 43.618 | S9: 17 | T9: 12.37 | U9: =SUM(P9:T9) -> 113.988 | V9: 1 | W9: 13 | X9: Итого производ - ность за смену | Z9: =SUM(Z5:Z8) -> 1157.732 | AC9: №4 | AD9: 32 | AE9: 7 | AF9: =AE9*11/60 -> 1.2833333
A10: 14 | E10: 53 | P10: 41 | Q10: 0 | R10: 44.39 | S10: 32 | T10: 12.99 | U10: =SUM(P10:T10) -> 130.38 | W10: 14 | AC10: №5 | AD10: 11 | AE10: 8 | AF10: =AE10*11/60 -> 1.4666667
A11: 15 | P11: 1.8 | Q11: 0 | R11: 43.922 | S11: 33 | T11: 12.91 | U11: =SUM(P11:T11) -> 91.632 | V11: 1 | W11: 15 | X11: Руда с конвейера Сито 12 мм | AE11: 9 | AF11: =AE11*11/60 -> 1.65
A12: 16 | P12: 0 | Q12: 0 | R12: 42.507 | S12: 33 | T12: 13.08 | U12: =SUM(P12:T12) -> 88.587 | V12: 2 | W12: 16 | AB12: 0.45833333 | AC12: №1 | AD12: 41 | AE12: 10 | AF12: =AE12*11/60 -> 1.8333333
A13: 17 | C13: 57 | D13: 69 | E13: 57 | F13: 59 | G13: 40 | H13: 31 | I13: 15 | L13: 50 | M13: 47 | N13: 48 | O13: 72 | P13: 0 | Q13: 0 | R13: 41.524 | S13: 33 | T13: 12.93 | U13: =SUM(P13:T13) -> 87.454 | V13: 1 | W13: 17 | X13: Время | Y13: Мельница | Z13: + | AA13: - | AC13: №3 | AE13: 11 | AF13: =AE13*11/60 -> 2.0166667
A14: 18 | P14: 41 | Q14: 0 | R14: 43.925 | S14: 32 | T14: 13.47 | U14: =SUM(P14:T14) -> 130.395 | V14: 2 | W14: 18 | X14: 0.41666667 | Y14: Исходная руда №1 | Z14: 1.8 | AA14: =100-Z14 -> 98.2 | AC14: №4 | AE14: 12 | AF14: =AE14*11/60 -> 2.2
A15: 19 | B15: 68 | K15: 50 | P15: 41 | Q15: 0 | R15: 43.335 | S15: 34 | T15: 13.38 | U15: =SUM(P15:T15) -> 131.715 | V15: 2 | W15: 19 | Y15: Исходная руда №3 | AA15: =100-Z15 -> 100 | AC15: №5 | AD15: 11 | AE15: 13 | AF15: =AE15*11/60 -> 2.3833333
A16: 20 | P16: 41 | Q16: 0 | R16: 41.989 | S16: 33 | T16: 13.26 | U16: =SUM(P16:T16) -> 129.249 | V16: 4 | W16: 20 | Y16: Исходная руда №4 | AA16: =100-Z16 -> 100 | AE16: 14 | AF16: =AE16*11/60 -> 2.5666667
A17: среднее | B17: =AVERAGE(B5:B15) -> 66.5 | C17: =AVERAGE(C5:C16) -> 53.5 | D17: =AVERAGE(D5:D15) -> 70.5 | E17: =AVERAGE(E5:E15) -> 55 | F17: =AVERAGE(F5:F15) -> 58.5 | G17: =AVERAGE(G5:G16) -> 39.5 | H17: =AVERAGE(H5:H16) -> 32 | I17: =AVERAGE(I5:I15) -> 7.5 | J17: =AVERAGE(J5:J15) -> #DIV/0! | K17: =AVERAGE(K5:K15) -> 49.5 | L17: =AVERAGE(L5:L15) -> 51.5 | M17: =AVERAGE(M5:M15) -> 49 | N17: =AVERAGE(N5:N15) -> 53 | O17: =AVERAGE(O5:O16) -> 71 | P17: =SUM(P5:P16) -> 363.3 | Q17: =SUM(Q5:Q16) -> 0 | R17: =SUM(R5:R16) -> 376.492 | S17: =SUM(S5:S16) -> 264 | T17: =SUM(T5:T16) -> 153.94 | U17: =SUM(P17:T17) -> 1157.732 | V17: =SUM(V5:V16) -> 17 | Y17: Исходная руда №5 | Z17: 0.3 | AA17: =100-Z17 -> 99.7 | AB17: 0.54166667 | AC17: №1 | AD17: 43 | AE17: 15 | AF17: =AE17*11/60 -> 2.75
AA18: 98.95 | AC18: №3 | AD18: 43 | AE18: 16 | AF18: =AE18*11/60 -> 2.9333333
A19: Загрузка шаров мельниц | C19: Ø, мм | D19: тн | F19: Примечание | I19: Ситовый анализ 04.01.26 см 1 | M19: Влага руды, % | P19: 2.5 | R19: 2.2 | S19: 2.6 | T19: 2.8 | U19: =(U17-U20)/U17*100 -> 2.4651339 | X19: 0.5 | AA19: - | AC19: №4 | AD19: 31 | AE19: 17 | AF19: =AE19*11/60 -> 3.1166667
A20: №2 | C20: 30 | D20: 0.2 | F20: новые | K20: % | M20: Итого СМТ по весам за смену | P20: =(P17-(P17*P19/100)) -> 354.2175 | R20: =(R17-(R17*R19/100)) -> 368.20918 | S20: =(S17-(S17*S19/100)) -> 257.136 | T20: =(T17-(T17*T19/100)) -> 149.62968 | U20: =P20+Q20+R20+S20+T20 -> 1129.1924 | Y20: Исходная руда №1 | Z20: 0.9 | AA20: =100-Z20 -> 99.1 | AC20: №5 | AD20: 10 | AE20: 18 | AF20: =AE20*11/60 -> 3.3
A21: №3 | C21: 60 | D21: 0.2 | F21: новые | I21: ГЦ№1 | J21: 51 | M21: Итого СМТ замер за смену | P21: =(U17-(U17*U19/100)) -> 1129.1924 | Y21: Исходная руда №3 | Z21: 1.3 | AA21: =100-Z21 -> 98.7 | AE21: 19 | AF21: =AE21*11/60 -> 3.4833333
